[2022-01-19 11:42:43,080] {processor.py:163} INFO - Started process (PID=328) to work on /opt/airflow/dags/Backup_Airflow_Data_to_S3.py
[2022-01-19 11:42:43,083] {processor.py:620} INFO - Processing file /opt/airflow/dags/Backup_Airflow_Data_to_S3.py for tasks to queue
[2022-01-19 11:42:43,086] {logging_mixin.py:109} INFO - [2022-01-19 11:42:43,086] {dagbag.py:500} INFO - Filling up the DagBag from /opt/airflow/dags/Backup_Airflow_Data_to_S3.py
[2022-01-19 11:42:43,725] {logging_mixin.py:109} INFO - [2022-01-19 11:42:43,719] {dagbag.py:334} ERROR - Failed to import: /opt/airflow/dags/Backup_Airflow_Data_to_S3.py
Traceback (most recent call last):
  File "/home/airflow/.local/lib/python3.7/site-packages/airflow/models/dagbag.py", line 331, in _load_modules_from_file
    loader.exec_module(new_module)
  File "<frozen importlib._bootstrap_external>", line 728, in exec_module
  File "<frozen importlib._bootstrap>", line 219, in _call_with_frames_removed
  File "/opt/airflow/dags/Backup_Airflow_Data_to_S3.py", line 11, in <module>
    from plugins import file_ops
ImportError: cannot import name 'file_ops' from 'plugins' (unknown location)
[2022-01-19 11:42:43,754] {processor.py:634} WARNING - No viable dags retrieved from /opt/airflow/dags/Backup_Airflow_Data_to_S3.py
[2022-01-19 11:42:43,773] {processor.py:171} INFO - Processing /opt/airflow/dags/Backup_Airflow_Data_to_S3.py took 0.700 seconds
[2022-01-19 11:45:35,767] {processor.py:163} INFO - Started process (PID=750) to work on /opt/airflow/dags/Backup_Airflow_Data_to_S3.py
[2022-01-19 11:45:35,773] {processor.py:620} INFO - Processing file /opt/airflow/dags/Backup_Airflow_Data_to_S3.py for tasks to queue
[2022-01-19 11:45:35,778] {logging_mixin.py:109} INFO - [2022-01-19 11:45:35,777] {dagbag.py:500} INFO - Filling up the DagBag from /opt/airflow/dags/Backup_Airflow_Data_to_S3.py
[2022-01-19 11:45:36,520] {logging_mixin.py:109} INFO - [2022-01-19 11:45:36,513] {dagbag.py:334} ERROR - Failed to import: /opt/airflow/dags/Backup_Airflow_Data_to_S3.py
Traceback (most recent call last):
  File "/home/airflow/.local/lib/python3.7/site-packages/airflow/models/dagbag.py", line 331, in _load_modules_from_file
    loader.exec_module(new_module)
  File "<frozen importlib._bootstrap_external>", line 728, in exec_module
  File "<frozen importlib._bootstrap>", line 219, in _call_with_frames_removed
  File "/opt/airflow/dags/Backup_Airflow_Data_to_S3.py", line 11, in <module>
    from plugins import file_ops
ImportError: cannot import name 'file_ops' from 'plugins' (unknown location)
[2022-01-19 11:45:36,553] {processor.py:634} WARNING - No viable dags retrieved from /opt/airflow/dags/Backup_Airflow_Data_to_S3.py
[2022-01-19 11:45:36,574] {processor.py:171} INFO - Processing /opt/airflow/dags/Backup_Airflow_Data_to_S3.py took 0.820 seconds
[2022-01-19 11:46:09,177] {processor.py:163} INFO - Started process (PID=890) to work on /opt/airflow/dags/Backup_Airflow_Data_to_S3.py
[2022-01-19 11:46:09,182] {processor.py:620} INFO - Processing file /opt/airflow/dags/Backup_Airflow_Data_to_S3.py for tasks to queue
[2022-01-19 11:46:09,185] {logging_mixin.py:109} INFO - [2022-01-19 11:46:09,184] {dagbag.py:500} INFO - Filling up the DagBag from /opt/airflow/dags/Backup_Airflow_Data_to_S3.py
[2022-01-19 11:46:09,912] {logging_mixin.py:109} INFO - [2022-01-19 11:46:09,897] {dagbag.py:334} ERROR - Failed to import: /opt/airflow/dags/Backup_Airflow_Data_to_S3.py
Traceback (most recent call last):
  File "/home/airflow/.local/lib/python3.7/site-packages/airflow/models/dagbag.py", line 331, in _load_modules_from_file
    loader.exec_module(new_module)
  File "<frozen importlib._bootstrap_external>", line 728, in exec_module
  File "<frozen importlib._bootstrap>", line 219, in _call_with_frames_removed
  File "/opt/airflow/dags/Backup_Airflow_Data_to_S3.py", line 11, in <module>
    from plugins import file_ops
ImportError: cannot import name 'file_ops' from 'plugins' (unknown location)
[2022-01-19 11:46:09,958] {processor.py:634} WARNING - No viable dags retrieved from /opt/airflow/dags/Backup_Airflow_Data_to_S3.py
[2022-01-19 11:46:09,978] {processor.py:171} INFO - Processing /opt/airflow/dags/Backup_Airflow_Data_to_S3.py took 0.809 seconds
[2022-01-19 11:46:41,654] {processor.py:163} INFO - Started process (PID=1018) to work on /opt/airflow/dags/Backup_Airflow_Data_to_S3.py
[2022-01-19 11:46:41,658] {processor.py:620} INFO - Processing file /opt/airflow/dags/Backup_Airflow_Data_to_S3.py for tasks to queue
[2022-01-19 11:46:41,662] {logging_mixin.py:109} INFO - [2022-01-19 11:46:41,661] {dagbag.py:500} INFO - Filling up the DagBag from /opt/airflow/dags/Backup_Airflow_Data_to_S3.py
[2022-01-19 11:46:42,300] {logging_mixin.py:109} INFO - [2022-01-19 11:46:42,294] {dagbag.py:334} ERROR - Failed to import: /opt/airflow/dags/Backup_Airflow_Data_to_S3.py
Traceback (most recent call last):
  File "/home/airflow/.local/lib/python3.7/site-packages/airflow/models/dagbag.py", line 331, in _load_modules_from_file
    loader.exec_module(new_module)
  File "<frozen importlib._bootstrap_external>", line 728, in exec_module
  File "<frozen importlib._bootstrap>", line 219, in _call_with_frames_removed
  File "/opt/airflow/dags/Backup_Airflow_Data_to_S3.py", line 11, in <module>
    from plugins import file_ops
ImportError: cannot import name 'file_ops' from 'plugins' (unknown location)
[2022-01-19 11:46:42,333] {processor.py:634} WARNING - No viable dags retrieved from /opt/airflow/dags/Backup_Airflow_Data_to_S3.py
[2022-01-19 11:46:42,351] {processor.py:171} INFO - Processing /opt/airflow/dags/Backup_Airflow_Data_to_S3.py took 0.705 seconds
[2022-01-19 11:47:14,797] {processor.py:163} INFO - Started process (PID=1161) to work on /opt/airflow/dags/Backup_Airflow_Data_to_S3.py
[2022-01-19 11:47:14,802] {processor.py:620} INFO - Processing file /opt/airflow/dags/Backup_Airflow_Data_to_S3.py for tasks to queue
[2022-01-19 11:47:14,806] {logging_mixin.py:109} INFO - [2022-01-19 11:47:14,805] {dagbag.py:500} INFO - Filling up the DagBag from /opt/airflow/dags/Backup_Airflow_Data_to_S3.py
[2022-01-19 11:47:15,520] {logging_mixin.py:109} INFO - [2022-01-19 11:47:15,509] {dagbag.py:334} ERROR - Failed to import: /opt/airflow/dags/Backup_Airflow_Data_to_S3.py
Traceback (most recent call last):
  File "/home/airflow/.local/lib/python3.7/site-packages/airflow/models/dagbag.py", line 331, in _load_modules_from_file
    loader.exec_module(new_module)
  File "<frozen importlib._bootstrap_external>", line 728, in exec_module
  File "<frozen importlib._bootstrap>", line 219, in _call_with_frames_removed
  File "/opt/airflow/dags/Backup_Airflow_Data_to_S3.py", line 11, in <module>
    from plugins import file_ops
ImportError: cannot import name 'file_ops' from 'plugins' (unknown location)
[2022-01-19 11:47:15,562] {processor.py:634} WARNING - No viable dags retrieved from /opt/airflow/dags/Backup_Airflow_Data_to_S3.py
[2022-01-19 11:47:15,584] {processor.py:171} INFO - Processing /opt/airflow/dags/Backup_Airflow_Data_to_S3.py took 0.794 seconds
[2022-01-19 11:47:48,062] {processor.py:163} INFO - Started process (PID=1303) to work on /opt/airflow/dags/Backup_Airflow_Data_to_S3.py
[2022-01-19 11:47:48,070] {processor.py:620} INFO - Processing file /opt/airflow/dags/Backup_Airflow_Data_to_S3.py for tasks to queue
[2022-01-19 11:47:48,074] {logging_mixin.py:109} INFO - [2022-01-19 11:47:48,073] {dagbag.py:500} INFO - Filling up the DagBag from /opt/airflow/dags/Backup_Airflow_Data_to_S3.py
[2022-01-19 11:47:48,841] {logging_mixin.py:109} INFO - [2022-01-19 11:47:48,835] {dagbag.py:334} ERROR - Failed to import: /opt/airflow/dags/Backup_Airflow_Data_to_S3.py
Traceback (most recent call last):
  File "/home/airflow/.local/lib/python3.7/site-packages/airflow/models/dagbag.py", line 331, in _load_modules_from_file
    loader.exec_module(new_module)
  File "<frozen importlib._bootstrap_external>", line 728, in exec_module
  File "<frozen importlib._bootstrap>", line 219, in _call_with_frames_removed
  File "/opt/airflow/dags/Backup_Airflow_Data_to_S3.py", line 11, in <module>
    from plugins import file_ops
ImportError: cannot import name 'file_ops' from 'plugins' (unknown location)
[2022-01-19 11:47:48,875] {processor.py:634} WARNING - No viable dags retrieved from /opt/airflow/dags/Backup_Airflow_Data_to_S3.py
[2022-01-19 11:47:48,894] {processor.py:171} INFO - Processing /opt/airflow/dags/Backup_Airflow_Data_to_S3.py took 0.840 seconds
[2022-01-19 11:48:21,108] {processor.py:163} INFO - Started process (PID=1431) to work on /opt/airflow/dags/Backup_Airflow_Data_to_S3.py
[2022-01-19 11:48:21,112] {processor.py:620} INFO - Processing file /opt/airflow/dags/Backup_Airflow_Data_to_S3.py for tasks to queue
[2022-01-19 11:48:21,115] {logging_mixin.py:109} INFO - [2022-01-19 11:48:21,115] {dagbag.py:500} INFO - Filling up the DagBag from /opt/airflow/dags/Backup_Airflow_Data_to_S3.py
[2022-01-19 11:48:21,753] {logging_mixin.py:109} INFO - [2022-01-19 11:48:21,747] {dagbag.py:334} ERROR - Failed to import: /opt/airflow/dags/Backup_Airflow_Data_to_S3.py
Traceback (most recent call last):
  File "/home/airflow/.local/lib/python3.7/site-packages/airflow/models/dagbag.py", line 331, in _load_modules_from_file
    loader.exec_module(new_module)
  File "<frozen importlib._bootstrap_external>", line 728, in exec_module
  File "<frozen importlib._bootstrap>", line 219, in _call_with_frames_removed
  File "/opt/airflow/dags/Backup_Airflow_Data_to_S3.py", line 11, in <module>
    from plugins import file_ops
ImportError: cannot import name 'file_ops' from 'plugins' (unknown location)
[2022-01-19 11:48:21,783] {processor.py:634} WARNING - No viable dags retrieved from /opt/airflow/dags/Backup_Airflow_Data_to_S3.py
[2022-01-19 11:48:21,802] {processor.py:171} INFO - Processing /opt/airflow/dags/Backup_Airflow_Data_to_S3.py took 0.701 seconds
[2022-01-19 11:48:54,454] {processor.py:163} INFO - Started process (PID=1574) to work on /opt/airflow/dags/Backup_Airflow_Data_to_S3.py
[2022-01-19 11:48:54,458] {processor.py:620} INFO - Processing file /opt/airflow/dags/Backup_Airflow_Data_to_S3.py for tasks to queue
[2022-01-19 11:48:54,462] {logging_mixin.py:109} INFO - [2022-01-19 11:48:54,461] {dagbag.py:500} INFO - Filling up the DagBag from /opt/airflow/dags/Backup_Airflow_Data_to_S3.py
[2022-01-19 11:48:55,243] {logging_mixin.py:109} INFO - [2022-01-19 11:48:55,236] {dagbag.py:334} ERROR - Failed to import: /opt/airflow/dags/Backup_Airflow_Data_to_S3.py
Traceback (most recent call last):
  File "/home/airflow/.local/lib/python3.7/site-packages/airflow/models/dagbag.py", line 331, in _load_modules_from_file
    loader.exec_module(new_module)
  File "<frozen importlib._bootstrap_external>", line 728, in exec_module
  File "<frozen importlib._bootstrap>", line 219, in _call_with_frames_removed
  File "/opt/airflow/dags/Backup_Airflow_Data_to_S3.py", line 11, in <module>
    from plugins import file_ops
ImportError: cannot import name 'file_ops' from 'plugins' (unknown location)
[2022-01-19 11:48:55,297] {processor.py:634} WARNING - No viable dags retrieved from /opt/airflow/dags/Backup_Airflow_Data_to_S3.py
[2022-01-19 11:48:55,325] {processor.py:171} INFO - Processing /opt/airflow/dags/Backup_Airflow_Data_to_S3.py took 0.884 seconds
[2022-01-19 11:49:27,712] {processor.py:163} INFO - Started process (PID=1712) to work on /opt/airflow/dags/Backup_Airflow_Data_to_S3.py
[2022-01-19 11:49:27,717] {processor.py:620} INFO - Processing file /opt/airflow/dags/Backup_Airflow_Data_to_S3.py for tasks to queue
[2022-01-19 11:49:27,720] {logging_mixin.py:109} INFO - [2022-01-19 11:49:27,719] {dagbag.py:500} INFO - Filling up the DagBag from /opt/airflow/dags/Backup_Airflow_Data_to_S3.py
[2022-01-19 11:49:28,508] {logging_mixin.py:109} INFO - [2022-01-19 11:49:28,503] {dagbag.py:334} ERROR - Failed to import: /opt/airflow/dags/Backup_Airflow_Data_to_S3.py
Traceback (most recent call last):
  File "/home/airflow/.local/lib/python3.7/site-packages/airflow/models/dagbag.py", line 331, in _load_modules_from_file
    loader.exec_module(new_module)
  File "<frozen importlib._bootstrap_external>", line 728, in exec_module
  File "<frozen importlib._bootstrap>", line 219, in _call_with_frames_removed
  File "/opt/airflow/dags/Backup_Airflow_Data_to_S3.py", line 11, in <module>
    from plugins import file_ops
ImportError: cannot import name 'file_ops' from 'plugins' (unknown location)
[2022-01-19 11:49:28,540] {processor.py:634} WARNING - No viable dags retrieved from /opt/airflow/dags/Backup_Airflow_Data_to_S3.py
[2022-01-19 11:49:28,560] {processor.py:171} INFO - Processing /opt/airflow/dags/Backup_Airflow_Data_to_S3.py took 0.857 seconds
[2022-01-19 11:50:00,551] {processor.py:163} INFO - Started process (PID=1844) to work on /opt/airflow/dags/Backup_Airflow_Data_to_S3.py
[2022-01-19 11:50:00,557] {processor.py:620} INFO - Processing file /opt/airflow/dags/Backup_Airflow_Data_to_S3.py for tasks to queue
[2022-01-19 11:50:00,560] {logging_mixin.py:109} INFO - [2022-01-19 11:50:00,559] {dagbag.py:500} INFO - Filling up the DagBag from /opt/airflow/dags/Backup_Airflow_Data_to_S3.py
[2022-01-19 11:50:01,191] {logging_mixin.py:109} INFO - [2022-01-19 11:50:01,186] {dagbag.py:334} ERROR - Failed to import: /opt/airflow/dags/Backup_Airflow_Data_to_S3.py
Traceback (most recent call last):
  File "/home/airflow/.local/lib/python3.7/site-packages/airflow/models/dagbag.py", line 331, in _load_modules_from_file
    loader.exec_module(new_module)
  File "<frozen importlib._bootstrap_external>", line 728, in exec_module
  File "<frozen importlib._bootstrap>", line 219, in _call_with_frames_removed
  File "/opt/airflow/dags/Backup_Airflow_Data_to_S3.py", line 11, in <module>
    from plugins import file_ops
ImportError: cannot import name 'file_ops' from 'plugins' (unknown location)
[2022-01-19 11:50:01,220] {processor.py:634} WARNING - No viable dags retrieved from /opt/airflow/dags/Backup_Airflow_Data_to_S3.py
[2022-01-19 11:50:01,237] {processor.py:171} INFO - Processing /opt/airflow/dags/Backup_Airflow_Data_to_S3.py took 0.693 seconds
[2022-01-19 11:50:33,941] {processor.py:163} INFO - Started process (PID=1993) to work on /opt/airflow/dags/Backup_Airflow_Data_to_S3.py
[2022-01-19 11:50:33,946] {processor.py:620} INFO - Processing file /opt/airflow/dags/Backup_Airflow_Data_to_S3.py for tasks to queue
[2022-01-19 11:50:33,948] {logging_mixin.py:109} INFO - [2022-01-19 11:50:33,948] {dagbag.py:500} INFO - Filling up the DagBag from /opt/airflow/dags/Backup_Airflow_Data_to_S3.py
[2022-01-19 11:50:34,635] {logging_mixin.py:109} INFO - [2022-01-19 11:50:34,629] {dagbag.py:334} ERROR - Failed to import: /opt/airflow/dags/Backup_Airflow_Data_to_S3.py
Traceback (most recent call last):
  File "/home/airflow/.local/lib/python3.7/site-packages/airflow/models/dagbag.py", line 331, in _load_modules_from_file
    loader.exec_module(new_module)
  File "<frozen importlib._bootstrap_external>", line 728, in exec_module
  File "<frozen importlib._bootstrap>", line 219, in _call_with_frames_removed
  File "/opt/airflow/dags/Backup_Airflow_Data_to_S3.py", line 11, in <module>
    from plugins import file_ops
ImportError: cannot import name 'file_ops' from 'plugins' (unknown location)
[2022-01-19 11:50:34,669] {processor.py:634} WARNING - No viable dags retrieved from /opt/airflow/dags/Backup_Airflow_Data_to_S3.py
[2022-01-19 11:50:34,689] {processor.py:171} INFO - Processing /opt/airflow/dags/Backup_Airflow_Data_to_S3.py took 0.755 seconds
[2022-01-19 11:54:33,875] {processor.py:163} INFO - Started process (PID=215) to work on /opt/airflow/dags/Backup_Airflow_Data_to_S3.py
[2022-01-19 11:54:33,880] {processor.py:620} INFO - Processing file /opt/airflow/dags/Backup_Airflow_Data_to_S3.py for tasks to queue
[2022-01-19 11:54:33,889] {logging_mixin.py:109} INFO - [2022-01-19 11:54:33,888] {dagbag.py:500} INFO - Filling up the DagBag from /opt/airflow/dags/Backup_Airflow_Data_to_S3.py
[2022-01-19 11:54:35,444] {logging_mixin.py:109} INFO - [2022-01-19 11:54:35,434] {dagbag.py:334} ERROR - Failed to import: /opt/airflow/dags/Backup_Airflow_Data_to_S3.py
Traceback (most recent call last):
  File "/home/airflow/.local/lib/python3.7/site-packages/airflow/models/dagbag.py", line 331, in _load_modules_from_file
    loader.exec_module(new_module)
  File "<frozen importlib._bootstrap_external>", line 728, in exec_module
  File "<frozen importlib._bootstrap>", line 219, in _call_with_frames_removed
  File "/opt/airflow/dags/Backup_Airflow_Data_to_S3.py", line 11, in <module>
    from plugins import file_ops
ImportError: cannot import name 'file_ops' from 'plugins' (unknown location)
[2022-01-19 11:54:35,519] {processor.py:634} WARNING - No viable dags retrieved from /opt/airflow/dags/Backup_Airflow_Data_to_S3.py
[2022-01-19 11:54:35,548] {processor.py:171} INFO - Processing /opt/airflow/dags/Backup_Airflow_Data_to_S3.py took 1.705 seconds
[2022-01-19 11:55:10,418] {processor.py:163} INFO - Started process (PID=361) to work on /opt/airflow/dags/Backup_Airflow_Data_to_S3.py
[2022-01-19 11:55:10,427] {processor.py:620} INFO - Processing file /opt/airflow/dags/Backup_Airflow_Data_to_S3.py for tasks to queue
[2022-01-19 11:55:10,440] {logging_mixin.py:109} INFO - [2022-01-19 11:55:10,440] {dagbag.py:500} INFO - Filling up the DagBag from /opt/airflow/dags/Backup_Airflow_Data_to_S3.py
[2022-01-19 11:55:11,174] {logging_mixin.py:109} INFO - [2022-01-19 11:55:11,168] {dagbag.py:334} ERROR - Failed to import: /opt/airflow/dags/Backup_Airflow_Data_to_S3.py
Traceback (most recent call last):
  File "/home/airflow/.local/lib/python3.7/site-packages/airflow/models/dagbag.py", line 331, in _load_modules_from_file
    loader.exec_module(new_module)
  File "<frozen importlib._bootstrap_external>", line 728, in exec_module
  File "<frozen importlib._bootstrap>", line 219, in _call_with_frames_removed
  File "/opt/airflow/dags/Backup_Airflow_Data_to_S3.py", line 11, in <module>
    from plugins import file_ops
ImportError: cannot import name 'file_ops' from 'plugins' (unknown location)
[2022-01-19 11:55:11,205] {processor.py:634} WARNING - No viable dags retrieved from /opt/airflow/dags/Backup_Airflow_Data_to_S3.py
[2022-01-19 11:55:11,229] {processor.py:171} INFO - Processing /opt/airflow/dags/Backup_Airflow_Data_to_S3.py took 0.818 seconds
[2022-01-19 11:55:43,884] {processor.py:163} INFO - Started process (PID=504) to work on /opt/airflow/dags/Backup_Airflow_Data_to_S3.py
[2022-01-19 11:55:43,888] {processor.py:620} INFO - Processing file /opt/airflow/dags/Backup_Airflow_Data_to_S3.py for tasks to queue
[2022-01-19 11:55:43,917] {logging_mixin.py:109} INFO - [2022-01-19 11:55:43,917] {dagbag.py:500} INFO - Filling up the DagBag from /opt/airflow/dags/Backup_Airflow_Data_to_S3.py
[2022-01-19 11:55:44,623] {logging_mixin.py:109} INFO - [2022-01-19 11:55:44,617] {dagbag.py:334} ERROR - Failed to import: /opt/airflow/dags/Backup_Airflow_Data_to_S3.py
Traceback (most recent call last):
  File "/home/airflow/.local/lib/python3.7/site-packages/airflow/models/dagbag.py", line 331, in _load_modules_from_file
    loader.exec_module(new_module)
  File "<frozen importlib._bootstrap_external>", line 728, in exec_module
  File "<frozen importlib._bootstrap>", line 219, in _call_with_frames_removed
  File "/opt/airflow/dags/Backup_Airflow_Data_to_S3.py", line 11, in <module>
    from plugins import file_ops
ImportError: cannot import name 'file_ops' from 'plugins' (unknown location)
[2022-01-19 11:55:44,654] {processor.py:634} WARNING - No viable dags retrieved from /opt/airflow/dags/Backup_Airflow_Data_to_S3.py
[2022-01-19 11:55:44,673] {processor.py:171} INFO - Processing /opt/airflow/dags/Backup_Airflow_Data_to_S3.py took 0.834 seconds
[2022-01-19 11:56:16,868] {processor.py:163} INFO - Started process (PID=632) to work on /opt/airflow/dags/Backup_Airflow_Data_to_S3.py
[2022-01-19 11:56:16,872] {processor.py:620} INFO - Processing file /opt/airflow/dags/Backup_Airflow_Data_to_S3.py for tasks to queue
[2022-01-19 11:56:16,876] {logging_mixin.py:109} INFO - [2022-01-19 11:56:16,875] {dagbag.py:500} INFO - Filling up the DagBag from /opt/airflow/dags/Backup_Airflow_Data_to_S3.py
[2022-01-19 11:56:17,621] {logging_mixin.py:109} INFO - [2022-01-19 11:56:17,615] {dagbag.py:334} ERROR - Failed to import: /opt/airflow/dags/Backup_Airflow_Data_to_S3.py
Traceback (most recent call last):
  File "/home/airflow/.local/lib/python3.7/site-packages/airflow/models/dagbag.py", line 331, in _load_modules_from_file
    loader.exec_module(new_module)
  File "<frozen importlib._bootstrap_external>", line 728, in exec_module
  File "<frozen importlib._bootstrap>", line 219, in _call_with_frames_removed
  File "/opt/airflow/dags/Backup_Airflow_Data_to_S3.py", line 11, in <module>
    from plugins import file_ops
ImportError: cannot import name 'file_ops' from 'plugins' (unknown location)
[2022-01-19 11:56:17,657] {processor.py:634} WARNING - No viable dags retrieved from /opt/airflow/dags/Backup_Airflow_Data_to_S3.py
[2022-01-19 11:56:17,676] {processor.py:171} INFO - Processing /opt/airflow/dags/Backup_Airflow_Data_to_S3.py took 0.815 seconds
[2022-01-19 11:56:49,673] {processor.py:163} INFO - Started process (PID=778) to work on /opt/airflow/dags/Backup_Airflow_Data_to_S3.py
[2022-01-19 11:56:49,677] {processor.py:620} INFO - Processing file /opt/airflow/dags/Backup_Airflow_Data_to_S3.py for tasks to queue
[2022-01-19 11:56:49,680] {logging_mixin.py:109} INFO - [2022-01-19 11:56:49,680] {dagbag.py:500} INFO - Filling up the DagBag from /opt/airflow/dags/Backup_Airflow_Data_to_S3.py
[2022-01-19 11:56:50,347] {logging_mixin.py:109} INFO - [2022-01-19 11:56:50,340] {dagbag.py:334} ERROR - Failed to import: /opt/airflow/dags/Backup_Airflow_Data_to_S3.py
Traceback (most recent call last):
  File "/home/airflow/.local/lib/python3.7/site-packages/airflow/models/dagbag.py", line 331, in _load_modules_from_file
    loader.exec_module(new_module)
  File "<frozen importlib._bootstrap_external>", line 728, in exec_module
  File "<frozen importlib._bootstrap>", line 219, in _call_with_frames_removed
  File "/opt/airflow/dags/Backup_Airflow_Data_to_S3.py", line 11, in <module>
    from plugins import file_ops
ImportError: cannot import name 'file_ops' from 'plugins' (unknown location)
[2022-01-19 11:56:50,378] {processor.py:634} WARNING - No viable dags retrieved from /opt/airflow/dags/Backup_Airflow_Data_to_S3.py
[2022-01-19 11:56:50,396] {processor.py:171} INFO - Processing /opt/airflow/dags/Backup_Airflow_Data_to_S3.py took 0.730 seconds
[2022-01-19 11:57:23,267] {processor.py:163} INFO - Started process (PID=921) to work on /opt/airflow/dags/Backup_Airflow_Data_to_S3.py
[2022-01-19 11:57:23,271] {processor.py:620} INFO - Processing file /opt/airflow/dags/Backup_Airflow_Data_to_S3.py for tasks to queue
[2022-01-19 11:57:23,274] {logging_mixin.py:109} INFO - [2022-01-19 11:57:23,274] {dagbag.py:500} INFO - Filling up the DagBag from /opt/airflow/dags/Backup_Airflow_Data_to_S3.py
[2022-01-19 11:57:23,962] {logging_mixin.py:109} INFO - [2022-01-19 11:57:23,957] {dagbag.py:334} ERROR - Failed to import: /opt/airflow/dags/Backup_Airflow_Data_to_S3.py
Traceback (most recent call last):
  File "/home/airflow/.local/lib/python3.7/site-packages/airflow/models/dagbag.py", line 331, in _load_modules_from_file
    loader.exec_module(new_module)
  File "<frozen importlib._bootstrap_external>", line 728, in exec_module
  File "<frozen importlib._bootstrap>", line 219, in _call_with_frames_removed
  File "/opt/airflow/dags/Backup_Airflow_Data_to_S3.py", line 11, in <module>
    from plugins import file_ops
ImportError: cannot import name 'file_ops' from 'plugins' (unknown location)
[2022-01-19 11:57:24,019] {processor.py:634} WARNING - No viable dags retrieved from /opt/airflow/dags/Backup_Airflow_Data_to_S3.py
[2022-01-19 11:57:24,056] {processor.py:171} INFO - Processing /opt/airflow/dags/Backup_Airflow_Data_to_S3.py took 0.808 seconds
[2022-01-19 11:57:55,871] {processor.py:163} INFO - Started process (PID=1047) to work on /opt/airflow/dags/Backup_Airflow_Data_to_S3.py
[2022-01-19 11:57:55,875] {processor.py:620} INFO - Processing file /opt/airflow/dags/Backup_Airflow_Data_to_S3.py for tasks to queue
[2022-01-19 11:57:55,878] {logging_mixin.py:109} INFO - [2022-01-19 11:57:55,877] {dagbag.py:500} INFO - Filling up the DagBag from /opt/airflow/dags/Backup_Airflow_Data_to_S3.py
[2022-01-19 11:57:56,464] {logging_mixin.py:109} INFO - [2022-01-19 11:57:56,458] {dagbag.py:334} ERROR - Failed to import: /opt/airflow/dags/Backup_Airflow_Data_to_S3.py
Traceback (most recent call last):
  File "/home/airflow/.local/lib/python3.7/site-packages/airflow/models/dagbag.py", line 331, in _load_modules_from_file
    loader.exec_module(new_module)
  File "<frozen importlib._bootstrap_external>", line 728, in exec_module
  File "<frozen importlib._bootstrap>", line 219, in _call_with_frames_removed
  File "/opt/airflow/dags/Backup_Airflow_Data_to_S3.py", line 11, in <module>
    from plugins import file_ops
ImportError: cannot import name 'file_ops' from 'plugins' (unknown location)
[2022-01-19 11:57:56,493] {processor.py:634} WARNING - No viable dags retrieved from /opt/airflow/dags/Backup_Airflow_Data_to_S3.py
[2022-01-19 11:57:56,511] {processor.py:171} INFO - Processing /opt/airflow/dags/Backup_Airflow_Data_to_S3.py took 0.646 seconds
[2022-01-19 12:04:27,205] {processor.py:163} INFO - Started process (PID=2516) to work on /opt/airflow/dags/Backup_Airflow_Data_to_S3.py
[2022-01-19 12:04:27,209] {processor.py:620} INFO - Processing file /opt/airflow/dags/Backup_Airflow_Data_to_S3.py for tasks to queue
[2022-01-19 12:04:27,213] {logging_mixin.py:109} INFO - [2022-01-19 12:04:27,212] {dagbag.py:500} INFO - Filling up the DagBag from /opt/airflow/dags/Backup_Airflow_Data_to_S3.py
[2022-01-19 12:04:27,840] {logging_mixin.py:109} INFO - [2022-01-19 12:04:27,834] {dagbag.py:334} ERROR - Failed to import: /opt/airflow/dags/Backup_Airflow_Data_to_S3.py
Traceback (most recent call last):
  File "/home/airflow/.local/lib/python3.7/site-packages/airflow/models/dagbag.py", line 331, in _load_modules_from_file
    loader.exec_module(new_module)
  File "<frozen importlib._bootstrap_external>", line 728, in exec_module
  File "<frozen importlib._bootstrap>", line 219, in _call_with_frames_removed
  File "/opt/airflow/dags/Backup_Airflow_Data_to_S3.py", line 11, in <module>
    from plugins import file_ops
ImportError: cannot import name 'file_ops' from 'plugins' (unknown location)
[2022-01-19 12:04:27,873] {processor.py:634} WARNING - No viable dags retrieved from /opt/airflow/dags/Backup_Airflow_Data_to_S3.py
[2022-01-19 12:04:27,892] {processor.py:171} INFO - Processing /opt/airflow/dags/Backup_Airflow_Data_to_S3.py took 0.694 seconds
[2022-01-19 12:04:58,588] {processor.py:163} INFO - Started process (PID=2647) to work on /opt/airflow/dags/Backup_Airflow_Data_to_S3.py
[2022-01-19 12:04:58,592] {processor.py:620} INFO - Processing file /opt/airflow/dags/Backup_Airflow_Data_to_S3.py for tasks to queue
[2022-01-19 12:04:58,596] {logging_mixin.py:109} INFO - [2022-01-19 12:04:58,595] {dagbag.py:500} INFO - Filling up the DagBag from /opt/airflow/dags/Backup_Airflow_Data_to_S3.py
[2022-01-19 12:04:59,169] {logging_mixin.py:109} INFO - [2022-01-19 12:04:59,163] {dagbag.py:334} ERROR - Failed to import: /opt/airflow/dags/Backup_Airflow_Data_to_S3.py
Traceback (most recent call last):
  File "/home/airflow/.local/lib/python3.7/site-packages/airflow/models/dagbag.py", line 331, in _load_modules_from_file
    loader.exec_module(new_module)
  File "<frozen importlib._bootstrap_external>", line 728, in exec_module
  File "<frozen importlib._bootstrap>", line 219, in _call_with_frames_removed
  File "/opt/airflow/dags/Backup_Airflow_Data_to_S3.py", line 11, in <module>
    from plugins import file_ops
ImportError: cannot import name 'file_ops' from 'plugins' (unknown location)
[2022-01-19 12:04:59,203] {processor.py:634} WARNING - No viable dags retrieved from /opt/airflow/dags/Backup_Airflow_Data_to_S3.py
[2022-01-19 12:04:59,222] {processor.py:171} INFO - Processing /opt/airflow/dags/Backup_Airflow_Data_to_S3.py took 0.643 seconds
[2022-01-19 12:05:30,918] {processor.py:163} INFO - Started process (PID=2774) to work on /opt/airflow/dags/Backup_Airflow_Data_to_S3.py
[2022-01-19 12:05:30,922] {processor.py:620} INFO - Processing file /opt/airflow/dags/Backup_Airflow_Data_to_S3.py for tasks to queue
[2022-01-19 12:05:30,926] {logging_mixin.py:109} INFO - [2022-01-19 12:05:30,925] {dagbag.py:500} INFO - Filling up the DagBag from /opt/airflow/dags/Backup_Airflow_Data_to_S3.py
[2022-01-19 12:05:31,453] {logging_mixin.py:109} INFO - [2022-01-19 12:05:31,447] {dagbag.py:334} ERROR - Failed to import: /opt/airflow/dags/Backup_Airflow_Data_to_S3.py
Traceback (most recent call last):
  File "/home/airflow/.local/lib/python3.7/site-packages/airflow/models/dagbag.py", line 331, in _load_modules_from_file
    loader.exec_module(new_module)
  File "<frozen importlib._bootstrap_external>", line 728, in exec_module
  File "<frozen importlib._bootstrap>", line 219, in _call_with_frames_removed
  File "/opt/airflow/dags/Backup_Airflow_Data_to_S3.py", line 11, in <module>
    from plugins import file_ops
ImportError: cannot import name 'file_ops' from 'plugins' (unknown location)
[2022-01-19 12:05:31,484] {processor.py:634} WARNING - No viable dags retrieved from /opt/airflow/dags/Backup_Airflow_Data_to_S3.py
[2022-01-19 12:05:31,501] {processor.py:171} INFO - Processing /opt/airflow/dags/Backup_Airflow_Data_to_S3.py took 0.591 seconds
[2022-01-19 12:06:04,130] {processor.py:163} INFO - Started process (PID=2912) to work on /opt/airflow/dags/Backup_Airflow_Data_to_S3.py
[2022-01-19 12:06:04,136] {processor.py:620} INFO - Processing file /opt/airflow/dags/Backup_Airflow_Data_to_S3.py for tasks to queue
[2022-01-19 12:06:04,140] {logging_mixin.py:109} INFO - [2022-01-19 12:06:04,140] {dagbag.py:500} INFO - Filling up the DagBag from /opt/airflow/dags/Backup_Airflow_Data_to_S3.py
[2022-01-19 12:06:04,677] {logging_mixin.py:109} INFO - [2022-01-19 12:06:04,666] {dagbag.py:334} ERROR - Failed to import: /opt/airflow/dags/Backup_Airflow_Data_to_S3.py
Traceback (most recent call last):
  File "/home/airflow/.local/lib/python3.7/site-packages/airflow/models/dagbag.py", line 331, in _load_modules_from_file
    loader.exec_module(new_module)
  File "<frozen importlib._bootstrap_external>", line 728, in exec_module
  File "<frozen importlib._bootstrap>", line 219, in _call_with_frames_removed
  File "/opt/airflow/dags/Backup_Airflow_Data_to_S3.py", line 11, in <module>
    from plugins import file_ops
ImportError: cannot import name 'file_ops' from 'plugins' (unknown location)
[2022-01-19 12:06:04,710] {processor.py:634} WARNING - No viable dags retrieved from /opt/airflow/dags/Backup_Airflow_Data_to_S3.py
[2022-01-19 12:06:04,730] {processor.py:171} INFO - Processing /opt/airflow/dags/Backup_Airflow_Data_to_S3.py took 0.609 seconds
[2022-01-19 12:06:36,923] {processor.py:163} INFO - Started process (PID=3034) to work on /opt/airflow/dags/Backup_Airflow_Data_to_S3.py
[2022-01-19 12:06:36,927] {processor.py:620} INFO - Processing file /opt/airflow/dags/Backup_Airflow_Data_to_S3.py for tasks to queue
[2022-01-19 12:06:36,930] {logging_mixin.py:109} INFO - [2022-01-19 12:06:36,930] {dagbag.py:500} INFO - Filling up the DagBag from /opt/airflow/dags/Backup_Airflow_Data_to_S3.py
[2022-01-19 12:06:37,423] {logging_mixin.py:109} INFO - [2022-01-19 12:06:37,416] {dagbag.py:334} ERROR - Failed to import: /opt/airflow/dags/Backup_Airflow_Data_to_S3.py
Traceback (most recent call last):
  File "/home/airflow/.local/lib/python3.7/site-packages/airflow/models/dagbag.py", line 331, in _load_modules_from_file
    loader.exec_module(new_module)
  File "<frozen importlib._bootstrap_external>", line 728, in exec_module
  File "<frozen importlib._bootstrap>", line 219, in _call_with_frames_removed
  File "/opt/airflow/dags/Backup_Airflow_Data_to_S3.py", line 11, in <module>
    from plugins import file_ops
ImportError: cannot import name 'file_ops' from 'plugins' (unknown location)
[2022-01-19 12:06:37,456] {processor.py:634} WARNING - No viable dags retrieved from /opt/airflow/dags/Backup_Airflow_Data_to_S3.py
[2022-01-19 12:06:37,477] {processor.py:171} INFO - Processing /opt/airflow/dags/Backup_Airflow_Data_to_S3.py took 0.560 seconds
[2022-01-19 12:07:07,965] {processor.py:163} INFO - Started process (PID=3166) to work on /opt/airflow/dags/Backup_Airflow_Data_to_S3.py
[2022-01-19 12:07:07,969] {processor.py:620} INFO - Processing file /opt/airflow/dags/Backup_Airflow_Data_to_S3.py for tasks to queue
[2022-01-19 12:07:07,974] {logging_mixin.py:109} INFO - [2022-01-19 12:07:07,973] {dagbag.py:500} INFO - Filling up the DagBag from /opt/airflow/dags/Backup_Airflow_Data_to_S3.py
[2022-01-19 12:07:08,485] {logging_mixin.py:109} INFO - [2022-01-19 12:07:08,480] {dagbag.py:334} ERROR - Failed to import: /opt/airflow/dags/Backup_Airflow_Data_to_S3.py
Traceback (most recent call last):
  File "/home/airflow/.local/lib/python3.7/site-packages/airflow/models/dagbag.py", line 331, in _load_modules_from_file
    loader.exec_module(new_module)
  File "<frozen importlib._bootstrap_external>", line 728, in exec_module
  File "<frozen importlib._bootstrap>", line 219, in _call_with_frames_removed
  File "/opt/airflow/dags/Backup_Airflow_Data_to_S3.py", line 11, in <module>
    from plugins import file_ops
ImportError: cannot import name 'file_ops' from 'plugins' (unknown location)
[2022-01-19 12:07:08,516] {processor.py:634} WARNING - No viable dags retrieved from /opt/airflow/dags/Backup_Airflow_Data_to_S3.py
[2022-01-19 12:07:08,533] {processor.py:171} INFO - Processing /opt/airflow/dags/Backup_Airflow_Data_to_S3.py took 0.575 seconds
[2022-01-19 12:07:38,779] {processor.py:163} INFO - Started process (PID=3292) to work on /opt/airflow/dags/Backup_Airflow_Data_to_S3.py
[2022-01-19 12:07:38,783] {processor.py:620} INFO - Processing file /opt/airflow/dags/Backup_Airflow_Data_to_S3.py for tasks to queue
[2022-01-19 12:07:38,786] {logging_mixin.py:109} INFO - [2022-01-19 12:07:38,786] {dagbag.py:500} INFO - Filling up the DagBag from /opt/airflow/dags/Backup_Airflow_Data_to_S3.py
[2022-01-19 12:07:39,324] {logging_mixin.py:109} INFO - [2022-01-19 12:07:39,317] {dagbag.py:334} ERROR - Failed to import: /opt/airflow/dags/Backup_Airflow_Data_to_S3.py
Traceback (most recent call last):
  File "/home/airflow/.local/lib/python3.7/site-packages/airflow/models/dagbag.py", line 331, in _load_modules_from_file
    loader.exec_module(new_module)
  File "<frozen importlib._bootstrap_external>", line 728, in exec_module
  File "<frozen importlib._bootstrap>", line 219, in _call_with_frames_removed
  File "/opt/airflow/dags/Backup_Airflow_Data_to_S3.py", line 11, in <module>
    from plugins import file_ops
ImportError: cannot import name 'file_ops' from 'plugins' (unknown location)
[2022-01-19 12:07:39,356] {processor.py:634} WARNING - No viable dags retrieved from /opt/airflow/dags/Backup_Airflow_Data_to_S3.py
[2022-01-19 12:07:39,376] {processor.py:171} INFO - Processing /opt/airflow/dags/Backup_Airflow_Data_to_S3.py took 0.605 seconds
[2022-01-19 12:08:09,538] {processor.py:163} INFO - Started process (PID=3419) to work on /opt/airflow/dags/Backup_Airflow_Data_to_S3.py
[2022-01-19 12:08:09,542] {processor.py:620} INFO - Processing file /opt/airflow/dags/Backup_Airflow_Data_to_S3.py for tasks to queue
[2022-01-19 12:08:09,546] {logging_mixin.py:109} INFO - [2022-01-19 12:08:09,545] {dagbag.py:500} INFO - Filling up the DagBag from /opt/airflow/dags/Backup_Airflow_Data_to_S3.py
[2022-01-19 12:08:10,054] {logging_mixin.py:109} INFO - [2022-01-19 12:08:10,048] {dagbag.py:334} ERROR - Failed to import: /opt/airflow/dags/Backup_Airflow_Data_to_S3.py
Traceback (most recent call last):
  File "/home/airflow/.local/lib/python3.7/site-packages/airflow/models/dagbag.py", line 331, in _load_modules_from_file
    loader.exec_module(new_module)
  File "<frozen importlib._bootstrap_external>", line 728, in exec_module
  File "<frozen importlib._bootstrap>", line 219, in _call_with_frames_removed
  File "/opt/airflow/dags/Backup_Airflow_Data_to_S3.py", line 11, in <module>
    from plugins import file_ops
ImportError: cannot import name 'file_ops' from 'plugins' (unknown location)
[2022-01-19 12:08:10,085] {processor.py:634} WARNING - No viable dags retrieved from /opt/airflow/dags/Backup_Airflow_Data_to_S3.py
[2022-01-19 12:08:10,103] {processor.py:171} INFO - Processing /opt/airflow/dags/Backup_Airflow_Data_to_S3.py took 0.573 seconds
[2022-01-19 12:08:40,750] {processor.py:163} INFO - Started process (PID=3556) to work on /opt/airflow/dags/Backup_Airflow_Data_to_S3.py
[2022-01-19 12:08:40,758] {processor.py:620} INFO - Processing file /opt/airflow/dags/Backup_Airflow_Data_to_S3.py for tasks to queue
[2022-01-19 12:08:40,761] {logging_mixin.py:109} INFO - [2022-01-19 12:08:40,761] {dagbag.py:500} INFO - Filling up the DagBag from /opt/airflow/dags/Backup_Airflow_Data_to_S3.py
[2022-01-19 12:08:41,300] {logging_mixin.py:109} INFO - [2022-01-19 12:08:41,294] {dagbag.py:334} ERROR - Failed to import: /opt/airflow/dags/Backup_Airflow_Data_to_S3.py
Traceback (most recent call last):
  File "/home/airflow/.local/lib/python3.7/site-packages/airflow/models/dagbag.py", line 331, in _load_modules_from_file
    loader.exec_module(new_module)
  File "<frozen importlib._bootstrap_external>", line 728, in exec_module
  File "<frozen importlib._bootstrap>", line 219, in _call_with_frames_removed
  File "/opt/airflow/dags/Backup_Airflow_Data_to_S3.py", line 11, in <module>
    from plugins import file_ops
ImportError: cannot import name 'file_ops' from 'plugins' (unknown location)
[2022-01-19 12:08:41,333] {processor.py:634} WARNING - No viable dags retrieved from /opt/airflow/dags/Backup_Airflow_Data_to_S3.py
[2022-01-19 12:08:41,352] {processor.py:171} INFO - Processing /opt/airflow/dags/Backup_Airflow_Data_to_S3.py took 0.619 seconds
[2022-01-19 12:10:00,609] {processor.py:163} INFO - Started process (PID=3853) to work on /opt/airflow/dags/Backup_Airflow_Data_to_S3.py
[2022-01-19 12:10:00,613] {processor.py:620} INFO - Processing file /opt/airflow/dags/Backup_Airflow_Data_to_S3.py for tasks to queue
[2022-01-19 12:10:00,616] {logging_mixin.py:109} INFO - [2022-01-19 12:10:00,616] {dagbag.py:500} INFO - Filling up the DagBag from /opt/airflow/dags/Backup_Airflow_Data_to_S3.py
[2022-01-19 12:10:00,660] {processor.py:634} WARNING - No viable dags retrieved from /opt/airflow/dags/Backup_Airflow_Data_to_S3.py
[2022-01-19 12:10:00,664] {processor.py:171} INFO - Processing /opt/airflow/dags/Backup_Airflow_Data_to_S3.py took 0.063 seconds
