[2022-01-19 11:42:32,447] {processor.py:163} INFO - Started process (PID=312) to work on /opt/airflow/dags/Cleanup_Log.py
[2022-01-19 11:42:32,452] {processor.py:620} INFO - Processing file /opt/airflow/dags/Cleanup_Log.py for tasks to queue
[2022-01-19 11:42:32,456] {logging_mixin.py:109} INFO - [2022-01-19 11:42:32,456] {dagbag.py:500} INFO - Filling up the DagBag from /opt/airflow/dags/Cleanup_Log.py
[2022-01-19 11:42:32,551] {logging_mixin.py:109} INFO - [2022-01-19 11:42:32,545] {dagbag.py:334} ERROR - Failed to import: /opt/airflow/dags/Cleanup_Log.py
Traceback (most recent call last):
  File "/home/airflow/.local/lib/python3.7/site-packages/airflow/models/dagbag.py", line 331, in _load_modules_from_file
    loader.exec_module(new_module)
  File "<frozen importlib._bootstrap_external>", line 728, in exec_module
  File "<frozen importlib._bootstrap>", line 219, in _call_with_frames_removed
  File "/opt/airflow/dags/Cleanup_Log.py", line 5, in <module>
    from plugins import util
ImportError: cannot import name 'util' from 'plugins' (unknown location)
[2022-01-19 11:42:32,590] {processor.py:634} WARNING - No viable dags retrieved from /opt/airflow/dags/Cleanup_Log.py
[2022-01-19 11:42:32,609] {processor.py:171} INFO - Processing /opt/airflow/dags/Cleanup_Log.py took 0.170 seconds
[2022-01-19 11:45:35,150] {processor.py:163} INFO - Started process (PID=744) to work on /opt/airflow/dags/Cleanup_Log.py
[2022-01-19 11:45:35,154] {processor.py:620} INFO - Processing file /opt/airflow/dags/Cleanup_Log.py for tasks to queue
[2022-01-19 11:45:35,157] {logging_mixin.py:109} INFO - [2022-01-19 11:45:35,157] {dagbag.py:500} INFO - Filling up the DagBag from /opt/airflow/dags/Cleanup_Log.py
[2022-01-19 11:45:35,207] {logging_mixin.py:109} INFO - [2022-01-19 11:45:35,202] {dagbag.py:334} ERROR - Failed to import: /opt/airflow/dags/Cleanup_Log.py
Traceback (most recent call last):
  File "/home/airflow/.local/lib/python3.7/site-packages/airflow/models/dagbag.py", line 331, in _load_modules_from_file
    loader.exec_module(new_module)
  File "<frozen importlib._bootstrap_external>", line 728, in exec_module
  File "<frozen importlib._bootstrap>", line 219, in _call_with_frames_removed
  File "/opt/airflow/dags/Cleanup_Log.py", line 5, in <module>
    from plugins import util
ImportError: cannot import name 'util' from 'plugins' (unknown location)
[2022-01-19 11:45:35,248] {processor.py:634} WARNING - No viable dags retrieved from /opt/airflow/dags/Cleanup_Log.py
[2022-01-19 11:45:35,274] {processor.py:171} INFO - Processing /opt/airflow/dags/Cleanup_Log.py took 0.131 seconds
[2022-01-19 11:46:08,468] {processor.py:163} INFO - Started process (PID=884) to work on /opt/airflow/dags/Cleanup_Log.py
[2022-01-19 11:46:08,473] {processor.py:620} INFO - Processing file /opt/airflow/dags/Cleanup_Log.py for tasks to queue
[2022-01-19 11:46:08,476] {logging_mixin.py:109} INFO - [2022-01-19 11:46:08,476] {dagbag.py:500} INFO - Filling up the DagBag from /opt/airflow/dags/Cleanup_Log.py
[2022-01-19 11:46:08,525] {logging_mixin.py:109} INFO - [2022-01-19 11:46:08,518] {dagbag.py:334} ERROR - Failed to import: /opt/airflow/dags/Cleanup_Log.py
Traceback (most recent call last):
  File "/home/airflow/.local/lib/python3.7/site-packages/airflow/models/dagbag.py", line 331, in _load_modules_from_file
    loader.exec_module(new_module)
  File "<frozen importlib._bootstrap_external>", line 728, in exec_module
  File "<frozen importlib._bootstrap>", line 219, in _call_with_frames_removed
  File "/opt/airflow/dags/Cleanup_Log.py", line 5, in <module>
    from plugins import util
ImportError: cannot import name 'util' from 'plugins' (unknown location)
[2022-01-19 11:46:08,563] {processor.py:634} WARNING - No viable dags retrieved from /opt/airflow/dags/Cleanup_Log.py
[2022-01-19 11:46:08,590] {processor.py:171} INFO - Processing /opt/airflow/dags/Cleanup_Log.py took 0.130 seconds
[2022-01-19 11:46:41,122] {processor.py:163} INFO - Started process (PID=1012) to work on /opt/airflow/dags/Cleanup_Log.py
[2022-01-19 11:46:41,126] {processor.py:620} INFO - Processing file /opt/airflow/dags/Cleanup_Log.py for tasks to queue
[2022-01-19 11:46:41,130] {logging_mixin.py:109} INFO - [2022-01-19 11:46:41,130] {dagbag.py:500} INFO - Filling up the DagBag from /opt/airflow/dags/Cleanup_Log.py
[2022-01-19 11:46:41,173] {logging_mixin.py:109} INFO - [2022-01-19 11:46:41,169] {dagbag.py:334} ERROR - Failed to import: /opt/airflow/dags/Cleanup_Log.py
Traceback (most recent call last):
  File "/home/airflow/.local/lib/python3.7/site-packages/airflow/models/dagbag.py", line 331, in _load_modules_from_file
    loader.exec_module(new_module)
  File "<frozen importlib._bootstrap_external>", line 728, in exec_module
  File "<frozen importlib._bootstrap>", line 219, in _call_with_frames_removed
  File "/opt/airflow/dags/Cleanup_Log.py", line 5, in <module>
    from plugins import util
ImportError: cannot import name 'util' from 'plugins' (unknown location)
[2022-01-19 11:46:41,203] {processor.py:634} WARNING - No viable dags retrieved from /opt/airflow/dags/Cleanup_Log.py
[2022-01-19 11:46:41,220] {processor.py:171} INFO - Processing /opt/airflow/dags/Cleanup_Log.py took 0.105 seconds
[2022-01-19 11:47:14,159] {processor.py:163} INFO - Started process (PID=1153) to work on /opt/airflow/dags/Cleanup_Log.py
[2022-01-19 11:47:14,173] {processor.py:620} INFO - Processing file /opt/airflow/dags/Cleanup_Log.py for tasks to queue
[2022-01-19 11:47:14,176] {logging_mixin.py:109} INFO - [2022-01-19 11:47:14,176] {dagbag.py:500} INFO - Filling up the DagBag from /opt/airflow/dags/Cleanup_Log.py
[2022-01-19 11:47:14,248] {logging_mixin.py:109} INFO - [2022-01-19 11:47:14,235] {dagbag.py:334} ERROR - Failed to import: /opt/airflow/dags/Cleanup_Log.py
Traceback (most recent call last):
  File "/home/airflow/.local/lib/python3.7/site-packages/airflow/models/dagbag.py", line 331, in _load_modules_from_file
    loader.exec_module(new_module)
  File "<frozen importlib._bootstrap_external>", line 728, in exec_module
  File "<frozen importlib._bootstrap>", line 219, in _call_with_frames_removed
  File "/opt/airflow/dags/Cleanup_Log.py", line 5, in <module>
    from plugins import util
ImportError: cannot import name 'util' from 'plugins' (unknown location)
[2022-01-19 11:47:14,293] {processor.py:634} WARNING - No viable dags retrieved from /opt/airflow/dags/Cleanup_Log.py
[2022-01-19 11:47:14,312] {processor.py:171} INFO - Processing /opt/airflow/dags/Cleanup_Log.py took 0.161 seconds
[2022-01-19 11:47:47,425] {processor.py:163} INFO - Started process (PID=1294) to work on /opt/airflow/dags/Cleanup_Log.py
[2022-01-19 11:47:47,439] {processor.py:620} INFO - Processing file /opt/airflow/dags/Cleanup_Log.py for tasks to queue
[2022-01-19 11:47:47,443] {logging_mixin.py:109} INFO - [2022-01-19 11:47:47,442] {dagbag.py:500} INFO - Filling up the DagBag from /opt/airflow/dags/Cleanup_Log.py
[2022-01-19 11:47:47,507] {logging_mixin.py:109} INFO - [2022-01-19 11:47:47,500] {dagbag.py:334} ERROR - Failed to import: /opt/airflow/dags/Cleanup_Log.py
Traceback (most recent call last):
  File "/home/airflow/.local/lib/python3.7/site-packages/airflow/models/dagbag.py", line 331, in _load_modules_from_file
    loader.exec_module(new_module)
  File "<frozen importlib._bootstrap_external>", line 728, in exec_module
  File "<frozen importlib._bootstrap>", line 219, in _call_with_frames_removed
  File "/opt/airflow/dags/Cleanup_Log.py", line 5, in <module>
    from plugins import util
ImportError: cannot import name 'util' from 'plugins' (unknown location)
[2022-01-19 11:47:47,569] {processor.py:634} WARNING - No viable dags retrieved from /opt/airflow/dags/Cleanup_Log.py
[2022-01-19 11:47:47,607] {processor.py:171} INFO - Processing /opt/airflow/dags/Cleanup_Log.py took 0.190 seconds
[2022-01-19 11:48:20,705] {processor.py:163} INFO - Started process (PID=1425) to work on /opt/airflow/dags/Cleanup_Log.py
[2022-01-19 11:48:20,709] {processor.py:620} INFO - Processing file /opt/airflow/dags/Cleanup_Log.py for tasks to queue
[2022-01-19 11:48:20,712] {logging_mixin.py:109} INFO - [2022-01-19 11:48:20,712] {dagbag.py:500} INFO - Filling up the DagBag from /opt/airflow/dags/Cleanup_Log.py
[2022-01-19 11:48:20,760] {logging_mixin.py:109} INFO - [2022-01-19 11:48:20,755] {dagbag.py:334} ERROR - Failed to import: /opt/airflow/dags/Cleanup_Log.py
Traceback (most recent call last):
  File "/home/airflow/.local/lib/python3.7/site-packages/airflow/models/dagbag.py", line 331, in _load_modules_from_file
    loader.exec_module(new_module)
  File "<frozen importlib._bootstrap_external>", line 728, in exec_module
  File "<frozen importlib._bootstrap>", line 219, in _call_with_frames_removed
  File "/opt/airflow/dags/Cleanup_Log.py", line 5, in <module>
    from plugins import util
ImportError: cannot import name 'util' from 'plugins' (unknown location)
[2022-01-19 11:48:20,791] {processor.py:634} WARNING - No viable dags retrieved from /opt/airflow/dags/Cleanup_Log.py
[2022-01-19 11:48:20,808] {processor.py:171} INFO - Processing /opt/airflow/dags/Cleanup_Log.py took 0.111 seconds
[2022-01-19 11:48:53,831] {processor.py:163} INFO - Started process (PID=1568) to work on /opt/airflow/dags/Cleanup_Log.py
[2022-01-19 11:48:53,836] {processor.py:620} INFO - Processing file /opt/airflow/dags/Cleanup_Log.py for tasks to queue
[2022-01-19 11:48:53,840] {logging_mixin.py:109} INFO - [2022-01-19 11:48:53,839] {dagbag.py:500} INFO - Filling up the DagBag from /opt/airflow/dags/Cleanup_Log.py
[2022-01-19 11:48:53,890] {logging_mixin.py:109} INFO - [2022-01-19 11:48:53,883] {dagbag.py:334} ERROR - Failed to import: /opt/airflow/dags/Cleanup_Log.py
Traceback (most recent call last):
  File "/home/airflow/.local/lib/python3.7/site-packages/airflow/models/dagbag.py", line 331, in _load_modules_from_file
    loader.exec_module(new_module)
  File "<frozen importlib._bootstrap_external>", line 728, in exec_module
  File "<frozen importlib._bootstrap>", line 219, in _call_with_frames_removed
  File "/opt/airflow/dags/Cleanup_Log.py", line 5, in <module>
    from plugins import util
ImportError: cannot import name 'util' from 'plugins' (unknown location)
[2022-01-19 11:48:53,941] {processor.py:634} WARNING - No viable dags retrieved from /opt/airflow/dags/Cleanup_Log.py
[2022-01-19 11:48:53,962] {processor.py:171} INFO - Processing /opt/airflow/dags/Cleanup_Log.py took 0.139 seconds
[2022-01-19 11:49:27,083] {processor.py:163} INFO - Started process (PID=1706) to work on /opt/airflow/dags/Cleanup_Log.py
[2022-01-19 11:49:27,088] {processor.py:620} INFO - Processing file /opt/airflow/dags/Cleanup_Log.py for tasks to queue
[2022-01-19 11:49:27,091] {logging_mixin.py:109} INFO - [2022-01-19 11:49:27,091] {dagbag.py:500} INFO - Filling up the DagBag from /opt/airflow/dags/Cleanup_Log.py
[2022-01-19 11:49:27,140] {logging_mixin.py:109} INFO - [2022-01-19 11:49:27,134] {dagbag.py:334} ERROR - Failed to import: /opt/airflow/dags/Cleanup_Log.py
Traceback (most recent call last):
  File "/home/airflow/.local/lib/python3.7/site-packages/airflow/models/dagbag.py", line 331, in _load_modules_from_file
    loader.exec_module(new_module)
  File "<frozen importlib._bootstrap_external>", line 728, in exec_module
  File "<frozen importlib._bootstrap>", line 219, in _call_with_frames_removed
  File "/opt/airflow/dags/Cleanup_Log.py", line 5, in <module>
    from plugins import util
ImportError: cannot import name 'util' from 'plugins' (unknown location)
[2022-01-19 11:49:27,174] {processor.py:634} WARNING - No viable dags retrieved from /opt/airflow/dags/Cleanup_Log.py
[2022-01-19 11:49:27,194] {processor.py:171} INFO - Processing /opt/airflow/dags/Cleanup_Log.py took 0.119 seconds
[2022-01-19 11:49:59,957] {processor.py:163} INFO - Started process (PID=1836) to work on /opt/airflow/dags/Cleanup_Log.py
[2022-01-19 11:49:59,961] {processor.py:620} INFO - Processing file /opt/airflow/dags/Cleanup_Log.py for tasks to queue
[2022-01-19 11:49:59,964] {logging_mixin.py:109} INFO - [2022-01-19 11:49:59,963] {dagbag.py:500} INFO - Filling up the DagBag from /opt/airflow/dags/Cleanup_Log.py
[2022-01-19 11:50:00,010] {logging_mixin.py:109} INFO - [2022-01-19 11:50:00,004] {dagbag.py:334} ERROR - Failed to import: /opt/airflow/dags/Cleanup_Log.py
Traceback (most recent call last):
  File "/home/airflow/.local/lib/python3.7/site-packages/airflow/models/dagbag.py", line 331, in _load_modules_from_file
    loader.exec_module(new_module)
  File "<frozen importlib._bootstrap_external>", line 728, in exec_module
  File "<frozen importlib._bootstrap>", line 219, in _call_with_frames_removed
  File "/opt/airflow/dags/Cleanup_Log.py", line 5, in <module>
    from plugins import util
ImportError: cannot import name 'util' from 'plugins' (unknown location)
[2022-01-19 11:50:00,043] {processor.py:634} WARNING - No viable dags retrieved from /opt/airflow/dags/Cleanup_Log.py
[2022-01-19 11:50:00,061] {processor.py:171} INFO - Processing /opt/airflow/dags/Cleanup_Log.py took 0.112 seconds
[2022-01-19 11:50:33,132] {processor.py:163} INFO - Started process (PID=1985) to work on /opt/airflow/dags/Cleanup_Log.py
[2022-01-19 11:50:33,137] {processor.py:620} INFO - Processing file /opt/airflow/dags/Cleanup_Log.py for tasks to queue
[2022-01-19 11:50:33,140] {logging_mixin.py:109} INFO - [2022-01-19 11:50:33,140] {dagbag.py:500} INFO - Filling up the DagBag from /opt/airflow/dags/Cleanup_Log.py
[2022-01-19 11:50:33,188] {logging_mixin.py:109} INFO - [2022-01-19 11:50:33,182] {dagbag.py:334} ERROR - Failed to import: /opt/airflow/dags/Cleanup_Log.py
Traceback (most recent call last):
  File "/home/airflow/.local/lib/python3.7/site-packages/airflow/models/dagbag.py", line 331, in _load_modules_from_file
    loader.exec_module(new_module)
  File "<frozen importlib._bootstrap_external>", line 728, in exec_module
  File "<frozen importlib._bootstrap>", line 219, in _call_with_frames_removed
  File "/opt/airflow/dags/Cleanup_Log.py", line 5, in <module>
    from plugins import util
ImportError: cannot import name 'util' from 'plugins' (unknown location)
[2022-01-19 11:50:33,221] {processor.py:634} WARNING - No viable dags retrieved from /opt/airflow/dags/Cleanup_Log.py
[2022-01-19 11:50:33,251] {processor.py:171} INFO - Processing /opt/airflow/dags/Cleanup_Log.py took 0.126 seconds
[2022-01-19 11:54:32,751] {processor.py:163} INFO - Started process (PID=209) to work on /opt/airflow/dags/Cleanup_Log.py
[2022-01-19 11:54:32,757] {processor.py:620} INFO - Processing file /opt/airflow/dags/Cleanup_Log.py for tasks to queue
[2022-01-19 11:54:32,775] {logging_mixin.py:109} INFO - [2022-01-19 11:54:32,775] {dagbag.py:500} INFO - Filling up the DagBag from /opt/airflow/dags/Cleanup_Log.py
[2022-01-19 11:54:32,863] {logging_mixin.py:109} INFO - [2022-01-19 11:54:32,855] {dagbag.py:334} ERROR - Failed to import: /opt/airflow/dags/Cleanup_Log.py
Traceback (most recent call last):
  File "/home/airflow/.local/lib/python3.7/site-packages/airflow/models/dagbag.py", line 331, in _load_modules_from_file
    loader.exec_module(new_module)
  File "<frozen importlib._bootstrap_external>", line 728, in exec_module
  File "<frozen importlib._bootstrap>", line 219, in _call_with_frames_removed
  File "/opt/airflow/dags/Cleanup_Log.py", line 5, in <module>
    from plugins import util
ImportError: cannot import name 'util' from 'plugins' (unknown location)
[2022-01-19 11:54:32,960] {processor.py:634} WARNING - No viable dags retrieved from /opt/airflow/dags/Cleanup_Log.py
[2022-01-19 11:54:33,004] {processor.py:171} INFO - Processing /opt/airflow/dags/Cleanup_Log.py took 0.272 seconds
[2022-01-19 11:55:09,834] {processor.py:163} INFO - Started process (PID=353) to work on /opt/airflow/dags/Cleanup_Log.py
[2022-01-19 11:55:09,842] {processor.py:620} INFO - Processing file /opt/airflow/dags/Cleanup_Log.py for tasks to queue
[2022-01-19 11:55:09,854] {logging_mixin.py:109} INFO - [2022-01-19 11:55:09,853] {dagbag.py:500} INFO - Filling up the DagBag from /opt/airflow/dags/Cleanup_Log.py
[2022-01-19 11:55:09,931] {logging_mixin.py:109} INFO - [2022-01-19 11:55:09,923] {dagbag.py:334} ERROR - Failed to import: /opt/airflow/dags/Cleanup_Log.py
Traceback (most recent call last):
  File "/home/airflow/.local/lib/python3.7/site-packages/airflow/models/dagbag.py", line 331, in _load_modules_from_file
    loader.exec_module(new_module)
  File "<frozen importlib._bootstrap_external>", line 728, in exec_module
  File "<frozen importlib._bootstrap>", line 219, in _call_with_frames_removed
  File "/opt/airflow/dags/Cleanup_Log.py", line 5, in <module>
    from plugins import util
ImportError: cannot import name 'util' from 'plugins' (unknown location)
[2022-01-19 11:55:09,969] {processor.py:634} WARNING - No viable dags retrieved from /opt/airflow/dags/Cleanup_Log.py
[2022-01-19 11:55:09,989] {processor.py:171} INFO - Processing /opt/airflow/dags/Cleanup_Log.py took 0.168 seconds
[2022-01-19 11:55:43,301] {processor.py:163} INFO - Started process (PID=499) to work on /opt/airflow/dags/Cleanup_Log.py
[2022-01-19 11:55:43,306] {processor.py:620} INFO - Processing file /opt/airflow/dags/Cleanup_Log.py for tasks to queue
[2022-01-19 11:55:43,310] {logging_mixin.py:109} INFO - [2022-01-19 11:55:43,310] {dagbag.py:500} INFO - Filling up the DagBag from /opt/airflow/dags/Cleanup_Log.py
[2022-01-19 11:55:43,357] {logging_mixin.py:109} INFO - [2022-01-19 11:55:43,352] {dagbag.py:334} ERROR - Failed to import: /opt/airflow/dags/Cleanup_Log.py
Traceback (most recent call last):
  File "/home/airflow/.local/lib/python3.7/site-packages/airflow/models/dagbag.py", line 331, in _load_modules_from_file
    loader.exec_module(new_module)
  File "<frozen importlib._bootstrap_external>", line 728, in exec_module
  File "<frozen importlib._bootstrap>", line 219, in _call_with_frames_removed
  File "/opt/airflow/dags/Cleanup_Log.py", line 5, in <module>
    from plugins import util
ImportError: cannot import name 'util' from 'plugins' (unknown location)
[2022-01-19 11:55:43,401] {processor.py:634} WARNING - No viable dags retrieved from /opt/airflow/dags/Cleanup_Log.py
[2022-01-19 11:55:43,422] {processor.py:171} INFO - Processing /opt/airflow/dags/Cleanup_Log.py took 0.139 seconds
[2022-01-19 11:56:16,540] {processor.py:163} INFO - Started process (PID=626) to work on /opt/airflow/dags/Cleanup_Log.py
[2022-01-19 11:56:16,544] {processor.py:620} INFO - Processing file /opt/airflow/dags/Cleanup_Log.py for tasks to queue
[2022-01-19 11:56:16,546] {logging_mixin.py:109} INFO - [2022-01-19 11:56:16,546] {dagbag.py:500} INFO - Filling up the DagBag from /opt/airflow/dags/Cleanup_Log.py
[2022-01-19 11:56:16,590] {logging_mixin.py:109} INFO - [2022-01-19 11:56:16,585] {dagbag.py:334} ERROR - Failed to import: /opt/airflow/dags/Cleanup_Log.py
Traceback (most recent call last):
  File "/home/airflow/.local/lib/python3.7/site-packages/airflow/models/dagbag.py", line 331, in _load_modules_from_file
    loader.exec_module(new_module)
  File "<frozen importlib._bootstrap_external>", line 728, in exec_module
  File "<frozen importlib._bootstrap>", line 219, in _call_with_frames_removed
  File "/opt/airflow/dags/Cleanup_Log.py", line 5, in <module>
    from plugins import util
ImportError: cannot import name 'util' from 'plugins' (unknown location)
[2022-01-19 11:56:16,624] {processor.py:634} WARNING - No viable dags retrieved from /opt/airflow/dags/Cleanup_Log.py
[2022-01-19 11:56:16,641] {processor.py:171} INFO - Processing /opt/airflow/dags/Cleanup_Log.py took 0.108 seconds
[2022-01-19 11:56:49,158] {processor.py:163} INFO - Started process (PID=770) to work on /opt/airflow/dags/Cleanup_Log.py
[2022-01-19 11:56:49,162] {processor.py:620} INFO - Processing file /opt/airflow/dags/Cleanup_Log.py for tasks to queue
[2022-01-19 11:56:49,166] {logging_mixin.py:109} INFO - [2022-01-19 11:56:49,165] {dagbag.py:500} INFO - Filling up the DagBag from /opt/airflow/dags/Cleanup_Log.py
[2022-01-19 11:56:49,210] {logging_mixin.py:109} INFO - [2022-01-19 11:56:49,206] {dagbag.py:334} ERROR - Failed to import: /opt/airflow/dags/Cleanup_Log.py
Traceback (most recent call last):
  File "/home/airflow/.local/lib/python3.7/site-packages/airflow/models/dagbag.py", line 331, in _load_modules_from_file
    loader.exec_module(new_module)
  File "<frozen importlib._bootstrap_external>", line 728, in exec_module
  File "<frozen importlib._bootstrap>", line 219, in _call_with_frames_removed
  File "/opt/airflow/dags/Cleanup_Log.py", line 5, in <module>
    from plugins import util
ImportError: cannot import name 'util' from 'plugins' (unknown location)
[2022-01-19 11:56:49,241] {processor.py:634} WARNING - No viable dags retrieved from /opt/airflow/dags/Cleanup_Log.py
[2022-01-19 11:56:49,260] {processor.py:171} INFO - Processing /opt/airflow/dags/Cleanup_Log.py took 0.110 seconds
[2022-01-19 11:57:22,704] {processor.py:163} INFO - Started process (PID=915) to work on /opt/airflow/dags/Cleanup_Log.py
[2022-01-19 11:57:22,709] {processor.py:620} INFO - Processing file /opt/airflow/dags/Cleanup_Log.py for tasks to queue
[2022-01-19 11:57:22,713] {logging_mixin.py:109} INFO - [2022-01-19 11:57:22,713] {dagbag.py:500} INFO - Filling up the DagBag from /opt/airflow/dags/Cleanup_Log.py
[2022-01-19 11:57:22,776] {logging_mixin.py:109} INFO - [2022-01-19 11:57:22,770] {dagbag.py:334} ERROR - Failed to import: /opt/airflow/dags/Cleanup_Log.py
Traceback (most recent call last):
  File "/home/airflow/.local/lib/python3.7/site-packages/airflow/models/dagbag.py", line 331, in _load_modules_from_file
    loader.exec_module(new_module)
  File "<frozen importlib._bootstrap_external>", line 728, in exec_module
  File "<frozen importlib._bootstrap>", line 219, in _call_with_frames_removed
  File "/opt/airflow/dags/Cleanup_Log.py", line 5, in <module>
    from plugins import util
ImportError: cannot import name 'util' from 'plugins' (unknown location)
[2022-01-19 11:57:22,817] {processor.py:634} WARNING - No viable dags retrieved from /opt/airflow/dags/Cleanup_Log.py
[2022-01-19 11:57:22,839] {processor.py:171} INFO - Processing /opt/airflow/dags/Cleanup_Log.py took 0.148 seconds
[2022-01-19 11:57:55,512] {processor.py:163} INFO - Started process (PID=1041) to work on /opt/airflow/dags/Cleanup_Log.py
[2022-01-19 11:57:55,515] {processor.py:620} INFO - Processing file /opt/airflow/dags/Cleanup_Log.py for tasks to queue
[2022-01-19 11:57:55,518] {logging_mixin.py:109} INFO - [2022-01-19 11:57:55,518] {dagbag.py:500} INFO - Filling up the DagBag from /opt/airflow/dags/Cleanup_Log.py
[2022-01-19 11:57:55,557] {logging_mixin.py:109} INFO - [2022-01-19 11:57:55,551] {dagbag.py:334} ERROR - Failed to import: /opt/airflow/dags/Cleanup_Log.py
Traceback (most recent call last):
  File "/home/airflow/.local/lib/python3.7/site-packages/airflow/models/dagbag.py", line 331, in _load_modules_from_file
    loader.exec_module(new_module)
  File "<frozen importlib._bootstrap_external>", line 728, in exec_module
  File "<frozen importlib._bootstrap>", line 219, in _call_with_frames_removed
  File "/opt/airflow/dags/Cleanup_Log.py", line 5, in <module>
    from plugins import util
ImportError: cannot import name 'util' from 'plugins' (unknown location)
[2022-01-19 11:57:55,586] {processor.py:634} WARNING - No viable dags retrieved from /opt/airflow/dags/Cleanup_Log.py
[2022-01-19 11:57:55,605] {processor.py:171} INFO - Processing /opt/airflow/dags/Cleanup_Log.py took 0.100 seconds
[2022-01-19 11:58:22,934] {processor.py:163} INFO - Started process (PID=1201) to work on /opt/airflow/dags/Cleanup_Log.py
[2022-01-19 11:58:22,939] {processor.py:620} INFO - Processing file /opt/airflow/dags/Cleanup_Log.py for tasks to queue
[2022-01-19 11:58:22,942] {logging_mixin.py:109} INFO - [2022-01-19 11:58:22,942] {dagbag.py:500} INFO - Filling up the DagBag from /opt/airflow/dags/Cleanup_Log.py
[2022-01-19 11:58:22,989] {logging_mixin.py:109} INFO - [2022-01-19 11:58:22,983] {dagbag.py:334} ERROR - Failed to import: /opt/airflow/dags/Cleanup_Log.py
Traceback (most recent call last):
  File "/home/airflow/.local/lib/python3.7/site-packages/airflow/models/dagbag.py", line 331, in _load_modules_from_file
    loader.exec_module(new_module)
  File "<frozen importlib._bootstrap_external>", line 728, in exec_module
  File "<frozen importlib._bootstrap>", line 219, in _call_with_frames_removed
  File "/opt/airflow/dags/Cleanup_Log.py", line 5, in <module>
    from plugins import util
ImportError: cannot import name 'util' from 'plugins' (unknown location)
[2022-01-19 11:58:23,032] {processor.py:634} WARNING - No viable dags retrieved from /opt/airflow/dags/Cleanup_Log.py
[2022-01-19 11:58:23,053] {processor.py:171} INFO - Processing /opt/airflow/dags/Cleanup_Log.py took 0.126 seconds
[2022-01-19 12:04:25,309] {processor.py:163} INFO - Started process (PID=2510) to work on /opt/airflow/dags/Cleanup_Log.py
[2022-01-19 12:04:25,313] {processor.py:620} INFO - Processing file /opt/airflow/dags/Cleanup_Log.py for tasks to queue
[2022-01-19 12:04:25,317] {logging_mixin.py:109} INFO - [2022-01-19 12:04:25,317] {dagbag.py:500} INFO - Filling up the DagBag from /opt/airflow/dags/Cleanup_Log.py
[2022-01-19 12:04:25,376] {logging_mixin.py:109} INFO - [2022-01-19 12:04:25,370] {dagbag.py:334} ERROR - Failed to import: /opt/airflow/dags/Cleanup_Log.py
Traceback (most recent call last):
  File "/home/airflow/.local/lib/python3.7/site-packages/airflow/models/dagbag.py", line 331, in _load_modules_from_file
    loader.exec_module(new_module)
  File "<frozen importlib._bootstrap_external>", line 728, in exec_module
  File "<frozen importlib._bootstrap>", line 219, in _call_with_frames_removed
  File "/opt/airflow/dags/Cleanup_Log.py", line 5, in <module>
    from plugins import util
ImportError: cannot import name 'util' from 'plugins' (unknown location)
[2022-01-19 12:04:25,411] {processor.py:634} WARNING - No viable dags retrieved from /opt/airflow/dags/Cleanup_Log.py
[2022-01-19 12:04:25,431] {processor.py:171} INFO - Processing /opt/airflow/dags/Cleanup_Log.py took 0.130 seconds
[2022-01-19 12:04:57,549] {processor.py:163} INFO - Started process (PID=2639) to work on /opt/airflow/dags/Cleanup_Log.py
[2022-01-19 12:04:57,564] {processor.py:620} INFO - Processing file /opt/airflow/dags/Cleanup_Log.py for tasks to queue
[2022-01-19 12:04:57,568] {logging_mixin.py:109} INFO - [2022-01-19 12:04:57,567] {dagbag.py:500} INFO - Filling up the DagBag from /opt/airflow/dags/Cleanup_Log.py
[2022-01-19 12:04:57,639] {logging_mixin.py:109} INFO - [2022-01-19 12:04:57,632] {dagbag.py:334} ERROR - Failed to import: /opt/airflow/dags/Cleanup_Log.py
Traceback (most recent call last):
  File "/home/airflow/.local/lib/python3.7/site-packages/airflow/models/dagbag.py", line 331, in _load_modules_from_file
    loader.exec_module(new_module)
  File "<frozen importlib._bootstrap_external>", line 728, in exec_module
  File "<frozen importlib._bootstrap>", line 219, in _call_with_frames_removed
  File "/opt/airflow/dags/Cleanup_Log.py", line 5, in <module>
    from plugins import util
ImportError: cannot import name 'util' from 'plugins' (unknown location)
[2022-01-19 12:04:57,698] {processor.py:634} WARNING - No viable dags retrieved from /opt/airflow/dags/Cleanup_Log.py
[2022-01-19 12:04:57,716] {processor.py:171} INFO - Processing /opt/airflow/dags/Cleanup_Log.py took 0.175 seconds
[2022-01-19 12:05:28,425] {processor.py:163} INFO - Started process (PID=2760) to work on /opt/airflow/dags/Cleanup_Log.py
[2022-01-19 12:05:28,429] {processor.py:620} INFO - Processing file /opt/airflow/dags/Cleanup_Log.py for tasks to queue
[2022-01-19 12:05:28,432] {logging_mixin.py:109} INFO - [2022-01-19 12:05:28,432] {dagbag.py:500} INFO - Filling up the DagBag from /opt/airflow/dags/Cleanup_Log.py
[2022-01-19 12:05:28,476] {logging_mixin.py:109} INFO - [2022-01-19 12:05:28,471] {dagbag.py:334} ERROR - Failed to import: /opt/airflow/dags/Cleanup_Log.py
Traceback (most recent call last):
  File "/home/airflow/.local/lib/python3.7/site-packages/airflow/models/dagbag.py", line 331, in _load_modules_from_file
    loader.exec_module(new_module)
  File "<frozen importlib._bootstrap_external>", line 728, in exec_module
  File "<frozen importlib._bootstrap>", line 219, in _call_with_frames_removed
  File "/opt/airflow/dags/Cleanup_Log.py", line 5, in <module>
    from plugins import util
ImportError: cannot import name 'util' from 'plugins' (unknown location)
[2022-01-19 12:05:28,507] {processor.py:634} WARNING - No viable dags retrieved from /opt/airflow/dags/Cleanup_Log.py
[2022-01-19 12:05:28,526] {processor.py:171} INFO - Processing /opt/airflow/dags/Cleanup_Log.py took 0.108 seconds
[2022-01-19 12:05:58,704] {processor.py:163} INFO - Started process (PID=2886) to work on /opt/airflow/dags/Cleanup_Log.py
[2022-01-19 12:05:58,708] {processor.py:620} INFO - Processing file /opt/airflow/dags/Cleanup_Log.py for tasks to queue
[2022-01-19 12:05:58,711] {logging_mixin.py:109} INFO - [2022-01-19 12:05:58,710] {dagbag.py:500} INFO - Filling up the DagBag from /opt/airflow/dags/Cleanup_Log.py
[2022-01-19 12:05:58,756] {logging_mixin.py:109} INFO - [2022-01-19 12:05:58,750] {dagbag.py:334} ERROR - Failed to import: /opt/airflow/dags/Cleanup_Log.py
Traceback (most recent call last):
  File "/home/airflow/.local/lib/python3.7/site-packages/airflow/models/dagbag.py", line 331, in _load_modules_from_file
    loader.exec_module(new_module)
  File "<frozen importlib._bootstrap_external>", line 728, in exec_module
  File "<frozen importlib._bootstrap>", line 219, in _call_with_frames_removed
  File "/opt/airflow/dags/Cleanup_Log.py", line 5, in <module>
    from plugins import util
ImportError: cannot import name 'util' from 'plugins' (unknown location)
[2022-01-19 12:05:58,790] {processor.py:634} WARNING - No viable dags retrieved from /opt/airflow/dags/Cleanup_Log.py
[2022-01-19 12:05:58,813] {processor.py:171} INFO - Processing /opt/airflow/dags/Cleanup_Log.py took 0.118 seconds
[2022-01-19 12:06:29,078] {processor.py:163} INFO - Started process (PID=3013) to work on /opt/airflow/dags/Cleanup_Log.py
[2022-01-19 12:06:29,083] {processor.py:620} INFO - Processing file /opt/airflow/dags/Cleanup_Log.py for tasks to queue
[2022-01-19 12:06:29,086] {logging_mixin.py:109} INFO - [2022-01-19 12:06:29,085] {dagbag.py:500} INFO - Filling up the DagBag from /opt/airflow/dags/Cleanup_Log.py
[2022-01-19 12:06:29,142] {logging_mixin.py:109} INFO - [2022-01-19 12:06:29,137] {dagbag.py:334} ERROR - Failed to import: /opt/airflow/dags/Cleanup_Log.py
Traceback (most recent call last):
  File "/home/airflow/.local/lib/python3.7/site-packages/airflow/models/dagbag.py", line 331, in _load_modules_from_file
    loader.exec_module(new_module)
  File "<frozen importlib._bootstrap_external>", line 728, in exec_module
  File "<frozen importlib._bootstrap>", line 219, in _call_with_frames_removed
  File "/opt/airflow/dags/Cleanup_Log.py", line 5, in <module>
    from plugins import util
ImportError: cannot import name 'util' from 'plugins' (unknown location)
[2022-01-19 12:06:29,179] {processor.py:634} WARNING - No viable dags retrieved from /opt/airflow/dags/Cleanup_Log.py
[2022-01-19 12:06:29,211] {processor.py:171} INFO - Processing /opt/airflow/dags/Cleanup_Log.py took 0.140 seconds
[2022-01-19 12:06:59,403] {processor.py:163} INFO - Started process (PID=3152) to work on /opt/airflow/dags/Cleanup_Log.py
[2022-01-19 12:06:59,408] {processor.py:620} INFO - Processing file /opt/airflow/dags/Cleanup_Log.py for tasks to queue
[2022-01-19 12:06:59,413] {logging_mixin.py:109} INFO - [2022-01-19 12:06:59,412] {dagbag.py:500} INFO - Filling up the DagBag from /opt/airflow/dags/Cleanup_Log.py
[2022-01-19 12:06:59,462] {logging_mixin.py:109} INFO - [2022-01-19 12:06:59,456] {dagbag.py:334} ERROR - Failed to import: /opt/airflow/dags/Cleanup_Log.py
Traceback (most recent call last):
  File "/home/airflow/.local/lib/python3.7/site-packages/airflow/models/dagbag.py", line 331, in _load_modules_from_file
    loader.exec_module(new_module)
  File "<frozen importlib._bootstrap_external>", line 728, in exec_module
  File "<frozen importlib._bootstrap>", line 219, in _call_with_frames_removed
  File "/opt/airflow/dags/Cleanup_Log.py", line 5, in <module>
    from plugins import util
ImportError: cannot import name 'util' from 'plugins' (unknown location)
[2022-01-19 12:06:59,508] {processor.py:634} WARNING - No viable dags retrieved from /opt/airflow/dags/Cleanup_Log.py
[2022-01-19 12:06:59,528] {processor.py:171} INFO - Processing /opt/airflow/dags/Cleanup_Log.py took 0.131 seconds
[2022-01-19 12:07:30,125] {processor.py:163} INFO - Started process (PID=3273) to work on /opt/airflow/dags/Cleanup_Log.py
[2022-01-19 12:07:30,129] {processor.py:620} INFO - Processing file /opt/airflow/dags/Cleanup_Log.py for tasks to queue
[2022-01-19 12:07:30,133] {logging_mixin.py:109} INFO - [2022-01-19 12:07:30,132] {dagbag.py:500} INFO - Filling up the DagBag from /opt/airflow/dags/Cleanup_Log.py
[2022-01-19 12:07:30,173] {logging_mixin.py:109} INFO - [2022-01-19 12:07:30,168] {dagbag.py:334} ERROR - Failed to import: /opt/airflow/dags/Cleanup_Log.py
Traceback (most recent call last):
  File "/home/airflow/.local/lib/python3.7/site-packages/airflow/models/dagbag.py", line 331, in _load_modules_from_file
    loader.exec_module(new_module)
  File "<frozen importlib._bootstrap_external>", line 728, in exec_module
  File "<frozen importlib._bootstrap>", line 219, in _call_with_frames_removed
  File "/opt/airflow/dags/Cleanup_Log.py", line 5, in <module>
    from plugins import util
ImportError: cannot import name 'util' from 'plugins' (unknown location)
[2022-01-19 12:07:30,204] {processor.py:634} WARNING - No viable dags retrieved from /opt/airflow/dags/Cleanup_Log.py
[2022-01-19 12:07:30,223] {processor.py:171} INFO - Processing /opt/airflow/dags/Cleanup_Log.py took 0.106 seconds
[2022-01-19 12:08:00,766] {processor.py:163} INFO - Started process (PID=3411) to work on /opt/airflow/dags/Cleanup_Log.py
[2022-01-19 12:08:00,771] {processor.py:620} INFO - Processing file /opt/airflow/dags/Cleanup_Log.py for tasks to queue
[2022-01-19 12:08:00,776] {logging_mixin.py:109} INFO - [2022-01-19 12:08:00,775] {dagbag.py:500} INFO - Filling up the DagBag from /opt/airflow/dags/Cleanup_Log.py
[2022-01-19 12:08:00,835] {logging_mixin.py:109} INFO - [2022-01-19 12:08:00,830] {dagbag.py:334} ERROR - Failed to import: /opt/airflow/dags/Cleanup_Log.py
Traceback (most recent call last):
  File "/home/airflow/.local/lib/python3.7/site-packages/airflow/models/dagbag.py", line 331, in _load_modules_from_file
    loader.exec_module(new_module)
  File "<frozen importlib._bootstrap_external>", line 728, in exec_module
  File "<frozen importlib._bootstrap>", line 219, in _call_with_frames_removed
  File "/opt/airflow/dags/Cleanup_Log.py", line 5, in <module>
    from plugins import util
ImportError: cannot import name 'util' from 'plugins' (unknown location)
[2022-01-19 12:08:00,888] {processor.py:634} WARNING - No viable dags retrieved from /opt/airflow/dags/Cleanup_Log.py
[2022-01-19 12:08:00,916] {processor.py:171} INFO - Processing /opt/airflow/dags/Cleanup_Log.py took 0.161 seconds
[2022-01-19 12:08:31,198] {processor.py:163} INFO - Started process (PID=3531) to work on /opt/airflow/dags/Cleanup_Log.py
[2022-01-19 12:08:31,203] {processor.py:620} INFO - Processing file /opt/airflow/dags/Cleanup_Log.py for tasks to queue
[2022-01-19 12:08:31,209] {logging_mixin.py:109} INFO - [2022-01-19 12:08:31,208] {dagbag.py:500} INFO - Filling up the DagBag from /opt/airflow/dags/Cleanup_Log.py
[2022-01-19 12:08:31,258] {logging_mixin.py:109} INFO - [2022-01-19 12:08:31,252] {dagbag.py:334} ERROR - Failed to import: /opt/airflow/dags/Cleanup_Log.py
Traceback (most recent call last):
  File "/home/airflow/.local/lib/python3.7/site-packages/airflow/models/dagbag.py", line 331, in _load_modules_from_file
    loader.exec_module(new_module)
  File "<frozen importlib._bootstrap_external>", line 728, in exec_module
  File "<frozen importlib._bootstrap>", line 219, in _call_with_frames_removed
  File "/opt/airflow/dags/Cleanup_Log.py", line 5, in <module>
    from plugins import util
ImportError: cannot import name 'util' from 'plugins' (unknown location)
[2022-01-19 12:08:31,289] {processor.py:634} WARNING - No viable dags retrieved from /opt/airflow/dags/Cleanup_Log.py
[2022-01-19 12:08:31,310] {processor.py:171} INFO - Processing /opt/airflow/dags/Cleanup_Log.py took 0.120 seconds
[2022-01-19 12:10:00,424] {processor.py:163} INFO - Started process (PID=3847) to work on /opt/airflow/dags/Cleanup_Log.py
[2022-01-19 12:10:00,429] {processor.py:620} INFO - Processing file /opt/airflow/dags/Cleanup_Log.py for tasks to queue
[2022-01-19 12:10:00,432] {logging_mixin.py:109} INFO - [2022-01-19 12:10:00,432] {dagbag.py:500} INFO - Filling up the DagBag from /opt/airflow/dags/Cleanup_Log.py
[2022-01-19 12:10:00,474] {processor.py:634} WARNING - No viable dags retrieved from /opt/airflow/dags/Cleanup_Log.py
[2022-01-19 12:10:00,477] {processor.py:171} INFO - Processing /opt/airflow/dags/Cleanup_Log.py took 0.061 seconds
