*** Reading local file: /var/lib/airflow/logs/MySQLTOCsv/MySQLTOCsv/2022-01-29T07:20:00+00:00/1.log
[2022-01-29 17:20:05,118] {taskinstance.py:903} INFO - Dependencies all met for <TaskInstance: MySQLTOCsv.MySQLTOCsv 2022-01-29T07:20:00+00:00 [queued]>
[2022-01-29 17:20:05,165] {taskinstance.py:903} INFO - Dependencies all met for <TaskInstance: MySQLTOCsv.MySQLTOCsv 2022-01-29T07:20:00+00:00 [queued]>
[2022-01-29 17:20:05,165] {taskinstance.py:1095} INFO - 
--------------------------------------------------------------------------------
[2022-01-29 17:20:05,165] {taskinstance.py:1096} INFO - Starting attempt 1 of 1
[2022-01-29 17:20:05,165] {taskinstance.py:1097} INFO - 
--------------------------------------------------------------------------------
[2022-01-29 17:20:05,216] {taskinstance.py:1115} INFO - Executing <Task(PythonOperator): MySQLTOCsv> on 2022-01-29T07:20:00+00:00
[2022-01-29 17:20:05,219] {standard_task_runner.py:52} INFO - Started process 27682 to run task
[2022-01-29 17:20:05,227] {standard_task_runner.py:76} INFO - Running: ['***', 'tasks', 'run', 'MySQLTOCsv', 'MySQLTOCsv', '2022-01-29T07:20:00+00:00', '--job-id', '714', '--pool', 'default_pool', '--raw', '--subdir', 'DAGS_FOLDER/MySQLToCsv.py', '--cfg-path', '/tmp/tmpucsiyn8x', '--error-file', '/tmp/tmpsb26ipwx']
[2022-01-29 17:20:05,231] {standard_task_runner.py:77} INFO - Job 714: Subtask MySQLTOCsv
[2022-01-29 17:20:05,426] {logging_mixin.py:109} INFO - Running <TaskInstance: MySQLTOCsv.MySQLTOCsv 2022-01-29T07:20:00+00:00 [running]> on host 10.nate.com
[2022-01-29 17:20:05,787] {taskinstance.py:1254} INFO - Exporting the following env vars:
AIRFLOW_CTX_DAG_OWNER=***
AIRFLOW_CTX_DAG_ID=MySQLTOCsv
AIRFLOW_CTX_TASK_ID=MySQLTOCsv
AIRFLOW_CTX_EXECUTION_DATE=2022-01-29T07:20:00+00:00
AIRFLOW_CTX_DAG_RUN_ID=scheduled__2022-01-29T07:20:00+00:00
[2022-01-29 17:20:05,874] {logging_mixin.py:109} WARNING - --- Logging error ---
[2022-01-29 17:20:05,891] {logging_mixin.py:109} WARNING - Traceback (most recent call last):
[2022-01-29 17:20:05,891] {logging_mixin.py:109} WARNING -   File "/var/lib/***/dags/MySQLToCsv.py", line 46, in _get_MySQL_Connection
    charset=charset
[2022-01-29 17:20:05,891] {logging_mixin.py:109} WARNING -   File "/var/lib/***/.venv/lib64/python3.6/site-packages/pymysql/connections.py", line 353, in __init__
    self.connect()
[2022-01-29 17:20:05,891] {logging_mixin.py:109} WARNING -   File "/var/lib/***/.venv/lib64/python3.6/site-packages/pymysql/connections.py", line 633, in connect
    self._request_authentication()
[2022-01-29 17:20:05,891] {logging_mixin.py:109} WARNING -   File "/var/lib/***/.venv/lib64/python3.6/site-packages/pymysql/connections.py", line 907, in _request_authentication
    auth_packet = self._read_packet()
[2022-01-29 17:20:05,891] {logging_mixin.py:109} WARNING -   File "/var/lib/***/.venv/lib64/python3.6/site-packages/pymysql/connections.py", line 725, in _read_packet
    packet.raise_for_error()
[2022-01-29 17:20:05,892] {logging_mixin.py:109} WARNING -   File "/var/lib/***/.venv/lib64/python3.6/site-packages/pymysql/protocol.py", line 221, in raise_for_error
    err.raise_mysql_exception(self._data)
[2022-01-29 17:20:05,892] {logging_mixin.py:109} WARNING -   File "/var/lib/***/.venv/lib64/python3.6/site-packages/pymysql/err.py", line 143, in raise_mysql_exception
    raise errorclass(errno, errval)
[2022-01-29 17:20:05,892] {logging_mixin.py:109} WARNING - pymysql.err.OperationalError: (1045, "Access denied for user 'jueun'@'175.198.105.68' (using password: YES)")
[2022-01-29 17:20:05,892] {logging_mixin.py:109} WARNING - 
During handling of the above exception, another exception occurred:
[2022-01-29 17:20:05,892] {logging_mixin.py:109} WARNING - Traceback (most recent call last):
[2022-01-29 17:20:05,892] {logging_mixin.py:109} WARNING -   File "/usr/lib64/python3.6/logging/__init__.py", line 994, in emit
    msg = self.format(record)
[2022-01-29 17:20:05,892] {logging_mixin.py:109} WARNING -   File "/usr/lib64/python3.6/logging/__init__.py", line 840, in format
    return fmt.format(record)
[2022-01-29 17:20:05,892] {logging_mixin.py:109} WARNING -   File "/usr/lib64/python3.6/logging/__init__.py", line 577, in format
    record.message = record.getMessage()
[2022-01-29 17:20:05,892] {logging_mixin.py:109} WARNING -   File "/usr/lib64/python3.6/logging/__init__.py", line 338, in getMessage
    msg = msg % self.args
[2022-01-29 17:20:05,893] {logging_mixin.py:109} WARNING - TypeError: not all arguments converted during string formatting
[2022-01-29 17:20:05,893] {logging_mixin.py:109} WARNING - Call stack:
[2022-01-29 17:20:05,940] {logging_mixin.py:109} WARNING -   File "/var/lib/***/.venv/bin/***", line 8, in <module>
    sys.exit(main())
[2022-01-29 17:20:05,940] {logging_mixin.py:109} WARNING -   File "/var/lib/***/.venv/lib64/python3.6/site-packages/***/__main__.py", line 40, in main
    args.func(args)
[2022-01-29 17:20:05,940] {logging_mixin.py:109} WARNING -   File "/var/lib/***/.venv/lib64/python3.6/site-packages/***/cli/cli_parser.py", line 48, in command
    return func(*args, **kwargs)
[2022-01-29 17:20:05,940] {logging_mixin.py:109} WARNING -   File "/var/lib/***/.venv/lib64/python3.6/site-packages/***/utils/cli.py", line 92, in wrapper
    return f(*args, **kwargs)
[2022-01-29 17:20:05,940] {logging_mixin.py:109} WARNING -   File "/var/lib/***/.venv/lib64/python3.6/site-packages/***/cli/commands/scheduler_command.py", line 63, in scheduler
    job.run()
[2022-01-29 17:20:05,941] {logging_mixin.py:109} WARNING -   File "/var/lib/***/.venv/lib64/python3.6/site-packages/***/jobs/base_job.py", line 245, in run
    self._execute()
[2022-01-29 17:20:05,941] {logging_mixin.py:109} WARNING -   File "/var/lib/***/.venv/lib64/python3.6/site-packages/***/jobs/scheduler_job.py", line 687, in _execute
    self.executor.start()
[2022-01-29 17:20:05,941] {logging_mixin.py:109} WARNING -   File "/var/lib/***/.venv/lib64/python3.6/site-packages/***/executors/local_executor.py", line 353, in start
    self.impl.start()
[2022-01-29 17:20:05,941] {logging_mixin.py:109} WARNING -   File "/var/lib/***/.venv/lib64/python3.6/site-packages/***/executors/local_executor.py", line 298, in start
    worker.start()
[2022-01-29 17:20:05,941] {logging_mixin.py:109} WARNING -   File "/usr/lib64/python3.6/multiprocessing/process.py", line 105, in start
    self._popen = self._Popen(self)
[2022-01-29 17:20:05,941] {logging_mixin.py:109} WARNING -   File "/usr/lib64/python3.6/multiprocessing/context.py", line 223, in _Popen
    return _default_context.get_context().Process._Popen(process_obj)
[2022-01-29 17:20:05,941] {logging_mixin.py:109} WARNING -   File "/usr/lib64/python3.6/multiprocessing/context.py", line 277, in _Popen
    return Popen(process_obj)
[2022-01-29 17:20:05,941] {logging_mixin.py:109} WARNING -   File "/usr/lib64/python3.6/multiprocessing/popen_fork.py", line 19, in __init__
    self._launch(process_obj)
[2022-01-29 17:20:05,941] {logging_mixin.py:109} WARNING -   File "/usr/lib64/python3.6/multiprocessing/popen_fork.py", line 73, in _launch
    code = process_obj._bootstrap()
[2022-01-29 17:20:05,942] {logging_mixin.py:109} WARNING -   File "/usr/lib64/python3.6/multiprocessing/process.py", line 258, in _bootstrap
    self.run()
[2022-01-29 17:20:05,942] {logging_mixin.py:109} WARNING -   File "/var/lib/***/.venv/lib64/python3.6/site-packages/***/executors/local_executor.py", line 67, in run
    return super().run()
[2022-01-29 17:20:05,942] {logging_mixin.py:109} WARNING -   File "/usr/lib64/python3.6/multiprocessing/process.py", line 93, in run
    self._target(*self._args, **self._kwargs)
[2022-01-29 17:20:05,942] {logging_mixin.py:109} WARNING -   File "/var/lib/***/.venv/lib64/python3.6/site-packages/***/executors/local_executor.py", line 190, in do_work
    self.execute_work(key=key, command=command)
[2022-01-29 17:20:05,942] {logging_mixin.py:109} WARNING -   File "/var/lib/***/.venv/lib64/python3.6/site-packages/***/executors/local_executor.py", line 84, in execute_work
    state = self._execute_work_in_fork(command)
[2022-01-29 17:20:05,942] {logging_mixin.py:109} WARNING -   File "/var/lib/***/.venv/lib64/python3.6/site-packages/***/executors/local_executor.py", line 124, in _execute_work_in_fork
    args.func(args)
[2022-01-29 17:20:05,942] {logging_mixin.py:109} WARNING -   File "/var/lib/***/.venv/lib64/python3.6/site-packages/***/cli/cli_parser.py", line 48, in command
    return func(*args, **kwargs)
[2022-01-29 17:20:05,942] {logging_mixin.py:109} WARNING -   File "/var/lib/***/.venv/lib64/python3.6/site-packages/***/utils/cli.py", line 92, in wrapper
    return f(*args, **kwargs)
[2022-01-29 17:20:05,943] {logging_mixin.py:109} WARNING -   File "/var/lib/***/.venv/lib64/python3.6/site-packages/***/cli/commands/task_command.py", line 238, in task_run
    _run_task_by_selected_method(args, dag, ti)
[2022-01-29 17:20:05,943] {logging_mixin.py:109} WARNING -   File "/var/lib/***/.venv/lib64/python3.6/site-packages/***/cli/commands/task_command.py", line 64, in _run_task_by_selected_method
    _run_task_by_local_task_job(args, ti)
[2022-01-29 17:20:05,943] {logging_mixin.py:109} WARNING -   File "/var/lib/***/.venv/lib64/python3.6/site-packages/***/cli/commands/task_command.py", line 121, in _run_task_by_local_task_job
    run_job.run()
[2022-01-29 17:20:05,943] {logging_mixin.py:109} WARNING -   File "/var/lib/***/.venv/lib64/python3.6/site-packages/***/jobs/base_job.py", line 245, in run
    self._execute()
[2022-01-29 17:20:05,943] {logging_mixin.py:109} WARNING -   File "/var/lib/***/.venv/lib64/python3.6/site-packages/***/jobs/local_task_job.py", line 100, in _execute
    self.task_runner.start()
[2022-01-29 17:20:05,943] {logging_mixin.py:109} WARNING -   File "/var/lib/***/.venv/lib64/python3.6/site-packages/***/task/task_runner/standard_task_runner.py", line 41, in start
    self.process = self._start_by_fork()
[2022-01-29 17:20:05,943] {logging_mixin.py:109} WARNING -   File "/var/lib/***/.venv/lib64/python3.6/site-packages/***/task/task_runner/standard_task_runner.py", line 85, in _start_by_fork
    args.func(args, dag=self.dag)
[2022-01-29 17:20:05,943] {logging_mixin.py:109} WARNING -   File "/var/lib/***/.venv/lib64/python3.6/site-packages/***/cli/cli_parser.py", line 48, in command
    return func(*args, **kwargs)
[2022-01-29 17:20:05,944] {logging_mixin.py:109} WARNING -   File "/var/lib/***/.venv/lib64/python3.6/site-packages/***/utils/cli.py", line 92, in wrapper
    return f(*args, **kwargs)
[2022-01-29 17:20:05,944] {logging_mixin.py:109} WARNING -   File "/var/lib/***/.venv/lib64/python3.6/site-packages/***/cli/commands/task_command.py", line 238, in task_run
    _run_task_by_selected_method(args, dag, ti)
[2022-01-29 17:20:05,944] {logging_mixin.py:109} WARNING -   File "/var/lib/***/.venv/lib64/python3.6/site-packages/***/cli/commands/task_command.py", line 66, in _run_task_by_selected_method
    _run_raw_task(args, ti)
[2022-01-29 17:20:05,944] {logging_mixin.py:109} WARNING -   File "/var/lib/***/.venv/lib64/python3.6/site-packages/***/cli/commands/task_command.py", line 153, in _run_raw_task
    error_file=args.error_file,
[2022-01-29 17:20:05,944] {logging_mixin.py:109} WARNING -   File "/var/lib/***/.venv/lib64/python3.6/site-packages/***/utils/session.py", line 70, in wrapper
    return func(*args, session=session, **kwargs)
[2022-01-29 17:20:05,944] {logging_mixin.py:109} WARNING -   File "/var/lib/***/.venv/lib64/python3.6/site-packages/***/models/taskinstance.py", line 1165, in _run_raw_task
    self._prepare_and_execute_task_with_callbacks(context, task)
[2022-01-29 17:20:05,944] {logging_mixin.py:109} WARNING -   File "/var/lib/***/.venv/lib64/python3.6/site-packages/***/models/taskinstance.py", line 1283, in _prepare_and_execute_task_with_callbacks
    result = self._execute_task(context, task_copy)
[2022-01-29 17:20:05,944] {logging_mixin.py:109} WARNING -   File "/var/lib/***/.venv/lib64/python3.6/site-packages/***/models/taskinstance.py", line 1313, in _execute_task
    result = task_copy.execute(context=context)
[2022-01-29 17:20:05,944] {logging_mixin.py:109} WARNING -   File "/var/lib/***/.venv/lib64/python3.6/site-packages/***/operators/python.py", line 150, in execute
    return_value = self.execute_callable()
[2022-01-29 17:20:05,945] {logging_mixin.py:109} WARNING -   File "/var/lib/***/.venv/lib64/python3.6/site-packages/***/operators/python.py", line 161, in execute_callable
    return self.python_callable(*self.op_args, **self.op_kwargs)
[2022-01-29 17:20:05,945] {logging_mixin.py:109} WARNING -   File "/var/lib/***/dags/MySQLToCsv.py", line 79, in etl
    df = load()
[2022-01-29 17:20:05,945] {logging_mixin.py:109} WARNING -   File "/var/lib/***/dags/MySQLToCsv.py", line 70, in load
    cur = _get_MySQL_Connection()
[2022-01-29 17:20:05,945] {logging_mixin.py:109} WARNING -   File "/var/lib/***/dags/MySQLToCsv.py", line 51, in _get_MySQL_Connection
    logging.error('DB Connect Error : ',datetime.now().strftime('%Y.%m.%d.%H.%M') )
[2022-01-29 17:20:05,945] {logging_mixin.py:109} WARNING -   File "/usr/lib64/python3.6/logging/__init__.py", line 1869, in error
    root.error(msg, *args, **kwargs)
[2022-01-29 17:20:05,945] {logging_mixin.py:109} WARNING -   File "/usr/lib64/python3.6/logging/__init__.py", line 1337, in error
    self._log(ERROR, msg, args, **kwargs)
[2022-01-29 17:20:05,945] {logging_mixin.py:109} WARNING -   File "/usr/lib64/python3.6/logging/__init__.py", line 1444, in _log
    self.handle(record)
[2022-01-29 17:20:05,946] {logging_mixin.py:109} WARNING -   File "/usr/lib64/python3.6/logging/__init__.py", line 1454, in handle
    self.callHandlers(record)
[2022-01-29 17:20:05,946] {logging_mixin.py:109} WARNING -   File "/usr/lib64/python3.6/logging/__init__.py", line 1516, in callHandlers
    hdlr.handle(record)
[2022-01-29 17:20:05,946] {logging_mixin.py:109} WARNING -   File "/usr/lib64/python3.6/logging/__init__.py", line 865, in handle
    self.emit(record)
[2022-01-29 17:20:05,946] {logging_mixin.py:109} WARNING -   File "/var/lib/***/.venv/lib64/python3.6/site-packages/***/utils/log/file_task_handler.py", line 66, in emit
    self.handler.emit(record)
[2022-01-29 17:20:05,946] {logging_mixin.py:109} WARNING - Message: 'DB Connect Error : '
Arguments: ('2022.01.29.17.20',)
[2022-01-29 17:20:05,946] {taskinstance.py:1463} ERROR - Task failed with exception
Traceback (most recent call last):
  File "/var/lib/airflow/dags/MySQLToCsv.py", line 46, in _get_MySQL_Connection
    charset=charset
  File "/var/lib/airflow/.venv/lib64/python3.6/site-packages/pymysql/connections.py", line 353, in __init__
    self.connect()
  File "/var/lib/airflow/.venv/lib64/python3.6/site-packages/pymysql/connections.py", line 633, in connect
    self._request_authentication()
  File "/var/lib/airflow/.venv/lib64/python3.6/site-packages/pymysql/connections.py", line 907, in _request_authentication
    auth_packet = self._read_packet()
  File "/var/lib/airflow/.venv/lib64/python3.6/site-packages/pymysql/connections.py", line 725, in _read_packet
    packet.raise_for_error()
  File "/var/lib/airflow/.venv/lib64/python3.6/site-packages/pymysql/protocol.py", line 221, in raise_for_error
    err.raise_mysql_exception(self._data)
  File "/var/lib/airflow/.venv/lib64/python3.6/site-packages/pymysql/err.py", line 143, in raise_mysql_exception
    raise errorclass(errno, errval)
pymysql.err.OperationalError: (1045, "Access denied for user 'jueun'@'175.198.105.68' (using password: YES)")

During handling of the above exception, another exception occurred:

Traceback (most recent call last):
  File "/var/lib/airflow/.venv/lib64/python3.6/site-packages/airflow/models/taskinstance.py", line 1165, in _run_raw_task
    self._prepare_and_execute_task_with_callbacks(context, task)
  File "/var/lib/airflow/.venv/lib64/python3.6/site-packages/airflow/models/taskinstance.py", line 1283, in _prepare_and_execute_task_with_callbacks
    result = self._execute_task(context, task_copy)
  File "/var/lib/airflow/.venv/lib64/python3.6/site-packages/airflow/models/taskinstance.py", line 1313, in _execute_task
    result = task_copy.execute(context=context)
  File "/var/lib/airflow/.venv/lib64/python3.6/site-packages/airflow/operators/python.py", line 150, in execute
    return_value = self.execute_callable()
  File "/var/lib/airflow/.venv/lib64/python3.6/site-packages/airflow/operators/python.py", line 161, in execute_callable
    return self.python_callable(*self.op_args, **self.op_kwargs)
  File "/var/lib/airflow/dags/MySQLToCsv.py", line 79, in etl
    df = load()
  File "/var/lib/airflow/dags/MySQLToCsv.py", line 70, in load
    cur = _get_MySQL_Connection()
  File "/var/lib/airflow/dags/MySQLToCsv.py", line 52, in _get_MySQL_Connection
    logging.error(e.message)
AttributeError: 'OperationalError' object has no attribute 'message'
[2022-01-29 17:20:05,948] {taskinstance.py:1513} INFO - Marking task as FAILED. dag_id=MySQLTOCsv, task_id=MySQLTOCsv, execution_date=20220129T072000, start_date=20220129T082005, end_date=20220129T082005
[2022-01-29 17:20:06,038] {local_task_job.py:151} INFO - Task exited with return code 1
[2022-01-29 17:20:06,143] {local_task_job.py:261} INFO - 0 downstream tasks scheduled from follow-on schedule check
